Workbook

Sheet VERDICT
B2: ACOLHE — one tender, one answer
B3: =INPUTS!$C$8&" · "&TEXT(INPUTS!$C$5,"#,##0")&" kits · bid "&TEXT(INPUTS!$C$7,"0%")&" of R$"&TEXT(INPUTS!$C$6,"#,##0.00")&" · "&INPUTS!$C$9&" · supplier discount "&TEXT(INPUTS!$C$13,"0%")&" · paid day "&TEXT(INPUTS!$C$10,"0")
B5: VERDICT | C5: =IF(DEAL!$C$12="","NO BID — a cost leg is unknown, so there is no number to judge",IF(DEAL!$C$25<0,"NO — this lot loses money at your bid",IF(DEAL!$C$25<INPUTS!$C$29,"THIN — net "&TEXT(DEAL!$C$25,"0.0%")&" against a "&TEXT(INPUTS!$C$29,"0%")&" target. "&TEXT($C$43,"0")&" of 9 checks not passed.",IF($C$43>0,"PENCILS — but "&TEXT($C$43,"0")&" check(s) not passed. Read them before you bid.","PENCILS — all 9 checks pass"))))
B7: WHAT YOU MAKE
B8: On this one lot, after tax and fees | C8: =DEAL!$C$24 | D8: per kit | E8: =DEAL!$C$26 | G8: Take-home is after the fixed costs on INPUTS.
B9: Per hour of your own time | C9: =DEAL!$C$49 | D9: hours on this lot | E9: =DEAL!$C$48
B10: A YEAR OF LOTS LIKE THIS, take-home | C10: =DEAL!$C$53 | D10: lots a year assumed | E10: =DEAL!$C$50 | G10: Lots per year is an assumption (INPUTS!C32).
B11: …which is, per month | C11: =DEAL!$C$54 | D11: per month in US$ | E11: =DEAL!$C$55
B12: …for this many hours a month | C12: =DEAL!$C$56
B14: IS THAT REAL?
B15: Net margin on this lot | C15: =DEAL!$C$25 | D15: your target | E15: =INPUTS!$C$29
B16: Cash you must front for one lot | C16: =DEAL!$C$29 | D16: days it is out | E16: =DEAL!$C$30
B17: Annualised return on that cash | C17: =DEAL!$C$31
B18: Lots a year your CAPITAL can carry | C18: =DEAL!$C$62 | D18: lots you planned | E18: =DEAL!$C$50 | G18: The real ceiling on income: cash, not tenders.
B19: Revenue that plan implies (RBT12) | C19: =DEAL!$C$64 | D19: Simples rate it puts you in | E19: =DEAL!$C$65
B21: WHERE EVERY REAL OF BID PRICE GOES (per kit)
C22: R$ per kit | D22: % of bid
B23: Bid price per kit | C23: =DEAL!$C$15 | D23: =IF(OR($C$23="",$C$23=0,C23=""),"",C23/$C$23)
B24: Goods, after supplier discount | C24: =DEAL!$C$7 | D24: =IF(OR($C$23="",$C$23=0,C24=""),"",C24/$C$23) | G24: Goods + freight over ~94% and nothing saves it.
B25: Freight | C25: =DEAL!$C$10 | D25: =IF(OR($C$23="",$C$23=0,C25=""),"",C25/$C$23)
B26: Assembly | C26: =DEAL!$C$9 | D26: =IF(OR($C$23="",$C$23=0,C26=""),"",C26/$C$23)
B27: Allowance for unpriced lines + packaging | C27: =DEAL!$C$8+DEAL!$C$11 | D27: =IF(OR($C$23="",$C$23=0,C27=""),"",C27/$C$23)
B28: Simples + IRRF + platform fee | C28: =IF(INPUTS!$C$5=0,"",(DEAL!$C$21+DEAL!$C$22+DEAL!$C$23)/INPUTS!$C$5) | D28: =IF(OR($C$23="",$C$23=0,C28=""),"",C28/$C$23)
B29: LEFT OVER = net profit per kit | C29: =DEAL!$C$26 | D29: =IF(OR($C$23="",$C$23=0,C29=""),"",C29/$C$23)
B31: THE CHECKS — every one must pass
B32: Check | C32: Status | D32: What it would take
B33: 1. Cost is fully known | C33: =IF(DEAL!$C$12="","BLOCKED","PASS") | D33: =IF(DEAL!$C$12="","Assembly or freight is blank. Quote it — a blank is not a zero.","Total cost R$"&TEXT(DEAL!$C$12,"#,##0.00")&" per kit")
B34: 2. The lot makes money | C34: =IF(DEAL!$C$25="","—",IF(DEAL!$C$25<0,"FAIL","PASS")) | D34: =IF(DEAL!$C$25="","Cost unknown",IF(DEAL!$C$25<0,"You would have to bid at least "&TEXT(DEAL!$C$37,"0.0%")&" of estimate just to break even","Break-even bid is "&TEXT(DEAL!$C$37,"0.0%")&" of estimate; you are bidding "&TEXT(INPUTS!$C$7,"0.0%")))
B35: 3. It hits your target margin | C35: =IF(DEAL!$C$25="","—",IF(DEAL!$C$25>=INPUTS!$C$29,"PASS","THIN")) | D35: =IF(DEAL!$C$25="","Cost unknown",IF(DEAL!$C$25>=INPUTS!$C$29,"Clears target with room","Needs "&TEXT(DEAL!$C$40,"0.0%")&" off list from the supplier, OR freight under R$"&TEXT(DEAL!$C$43,"#,##0.00")&" per kit, OR a bid at "&TEXT(DEAL!$C$36,"0.0%")&" of estimate"))
B36: 4. You can fund one lot | C36: =IF(INPUTS!$C$28="","UNKNOWN",IF(DEAL!$C$29="","—",IF(DEAL!$C$29<=INPUTS!$C$28,"PASS","SHORT"))) | D36: =IF(INPUTS!$C$28="","Capital not set — put your real number in INPUTS!C28",IF(DEAL!$C$29="","Cost unknown",IF(DEAL!$C$29<=INPUTS!$C$28,"Needs R$"&TEXT(DEAL!$C$29,"#,##0")&" of the R$"&TEXT(INPUTS!$C$28,"#,##0")&" you have","Short by R$"&TEXT(DEAL!$C$29-INPUTS!$C$28,"#,##0")&" for "&TEXT(INPUTS!$C$10,"0")&" days")))
B37: 5. Your capital can carry the year you planned | C37: =IF(OR(DEAL!$C$62="",DEAL!$C$62=0),"UNKNOWN",IF(DEAL!$C$62>=DEAL!$C$50,"PASS","CAPPED")) | D37: =IF(OR(DEAL!$C$62="",DEAL!$C$62=0),"Set capital on INPUTS!C28 to answer this",IF(DEAL!$C$62>=DEAL!$C$50,"Capital supports "&TEXT(DEAL!$C$62,"#,##0.0")&" lots a year; you planned "&TEXT(DEAL!$C$50,"#,##0"),"Capital supports only "&TEXT(DEAL!$C$62,"#,##0.0")&" lots a year, not "&TEXT(DEAL!$C$50,"#,##0")&". Income is capped by cash, not by tenders. Supplier terms fix this for free; a loan costs money"))
B38: 6. You can pack it yourself | C38: =IF(INPUTS!$C$5<=INPUTS!$C$20,"PASS","NEEDS CO-PACKER") | D38: =IF(INPUTS!$C$5<=INPUTS!$C$20,TEXT(INPUTS!$C$5,"#,##0")&" kits is inside the "&TEXT(INPUTS!$C$20,"#,##0")&"-kit self-pack ceiling","Lot of "&TEXT(INPUTS!$C$5,"#,##0")&" exceeds the "&TEXT(INPUTS!$C$20,"#,##0")&"-kit ceiling. No SP co-packer publishes a price — get one before you bid")
B39: 7. The BOM is fully priced | C39: =IF(BOM!$E$23=0,"PASS","OPEN") | D39: =IF(BOM!$E$23=0,"All 17 lines priced",TEXT(BOM!$E$23,"0")&" line(s) unpriced. You are carrying R$"&TEXT(INPUTS!$C$17,"#,##0.00")&" of allowance against them — a guess, not a quote")
B40: 8. Freight is measured for this UF and mode | C40: =IF(INPUTS!$C$14<>"","PASS",IF(FREIGHT!$B$8="","NOT MEASURED","PASS")) | D40: =IF(INPUTS!$C$14<>"","Using your quoted override of R$"&TEXT(INPUTS!$C$14,"#,##0.00"),IF(FREIGHT!$B$8="","No measured rate for "&INPUTS!$C$8&" by "&INPUTS!$C$9&". Quote it, or change the mode","R$"&TEXT(FREIGHT!$B$8,"#,##0.00")&" per kit, measured to the CAPITAL CEP only — interior will differ"))
B41: 9. The tax bracket matches the year you planned | C41: =IF(ABS(DEAL!$C$65-DEAL!$C$20)<0.0001,"PASS","UNDERSTATED") | D41: =IF(ABS(DEAL!$C$65-DEAL!$C$20)<0.0001,"RBT12 on INPUTS matches the "&TEXT(DEAL!$C$64,"#,##0")&" of revenue your plan implies","You are taxed at "&TEXT(DEAL!$C$20,"0.00%")&" but "&TEXT(DEAL!$C$50,"#,##0")&" lots implies R$"&TEXT(DEAL!$C$64,"#,##0")&" of revenue, which is the "&TEXT(DEAL!$C$65,"0.00%")&" bracket. Raise INPUTS!C23")
B43: Checks not passed | C43: =SUMPRODUCT(--($C$33:$C$41<>"PASS")) | D43: out of 9
B45: WHAT WOULD HAVE TO BE TRUE
B46: Supplier discount off list needed to hit target | C46: =DEAL!$C$40 | D46: The single biggest lever in the model. 45% is the UNVERIFIED account-tier figure.
B47: Supplier discount needed merely to break even | C47: =DEAL!$C$42 | D47: Negative means list price alone already breaks even.
B48: Max freight per kit at target margin | C48: =DEAL!$C$43 | D48: Negative means no freight price on earth saves this bid.
...

Sheet INPUTS
B2: INPUTS — the only sheet you type on
B3: Every yellow cell is a number you choose or measure. Nothing anywhere else in this workbook is typed. One tender per copy of this file.
B4: THE TENDER
B5: Kits in the lot (quantidade) | C5: 61 | D5: For an SRP, the quantity you actually expect to be called off — not the ceiling.
B6: Buyer's estimated price per kit (valor estimado) | C6: 359.05 | D6: From the edital. R$359,05 was the Itaquaquecetuba 2025 estimate for a 17-item kit.
B7: My bid as % of the estimate | C7: 0.9 | D7: Per-item lines clear at 97–100% of estimate; lote unico at 36–63%.
B8: Buyer UF | C8: CE | D8: Two letters. Drives freight and transit from the FREIGHT sheet.
B9: Delivery mode: LTL or PARCEL | C9: LTL | D9: LTL only when the edital delivers the WHOLE lot to ONE address in one go. 'Parcelado' or per-ordem addresses = PARCEL.
B10: Days from empenho to cash in the bank | C10: 45 | D10: Measured on 7 editais: 34 best, 40–55 typical, 69 worst (docs/ORDER_TO_CASH.md).
B12: THE TWO LEVERS THAT DECIDE THIS DEAL
B13: Supplier discount off list (account tier) | C13: 0 | D13: 0% until an account is opened. ~45% is the UNVERIFIED account-tier figure — do not use it until it is quoted in writing.
B14: Freight per kit OVERRIDE (blank = use the table) | D14: A real quoted figure typed here replaces the FREIGHT table for this deal.
B16: COSTS NOT YET IN THE BOM
B17: Allowance for unpriced BOM lines | C17: 0 | D17: BOM has 1 unpriced line (the kit bag). Leaving this at 0 means bidding as if the bag is free.
B18: Packaging / box / label per kit | C18: 0 | D18: Not yet costed.
B19: Co-packer cost per kit (only if lot > ceiling) | D19: NO QUOTE EXISTS — 24 SP providers surveyed, none publishes a price. Blank = unknown, and the verdict blocks rather than assuming zero.
B20: Self-pack ceiling (kits you can pack per order) | C20: 240 | D20: config/capital.yaml: 8 h per won order at 2 min/kit.
B22: TAX, FEES, CAPITAL
B23: Revenue last 12 months (RBT12) | C23: 180000 | D23: Anexo I efetivo: ≤180k 4,00% · 360k 5,65% · 720k 7,58% · 1,8M ~9,1% · 3,6M ~11,9%. Tem de bater com a receita do ano que você planeia — é o que a verificação 9 compara.
B24: IRRF withheld by the buyer | C24: 0 | D24: 0% if the IN RFB 1.234 Anexo IV declaration is filed with every contract. 1,2% if it is not — and there is no refund path.
B25: Platform fee as % of lot value | C25: 0.015 | D25: BLL: 1,5% of the lote adjudicado, only on a win. Compras.gov.br: 0%.
B26: Platform fee cap (R$) | C26: 600 | D26: BLL caps at R$600 when the lote exceeds R$40.000. Use a huge number for no cap.
B27: Platform fixed fee per process (R$) | C27: 0 | D27: BNC R$118,80 / PCP R$129 per process, charged even when you lose. BLL and Compras.gov.br: 0.
B28: Capital available (R$) | C28: 15600 | D28: From the written plan. Confirm it — every capacity number in the model moves with this one cell. Blank it out and checks 4 and 5 say UNKNOWN instead of guessing.
B29: Target NET margin | C29: 0.15 | D29: What 'pencils' means to you. Change it and everything the verdict demands moves with it.
B31: TURNING ONE DEAL INTO A YEAR — this is what you actually take home
B32: Lots like this you expect to win in a year | C32: 8 | D32: The written plan's figure. It is an assumption: Brazil publishes winners, never losers, so no one can measure a win rate until they have bid. Check 5 tests it against your capital.
B33: Annual fixed costs (R$) | C33: 6000 | D33: Contador ~R$300/mo = 3.600, e-CNPJ ~250, domain + site ~300, server ~360, contingency. Estimated, not quoted.
B34: Your hours per won order | C34: 8 | D34: Constraint C9 in the plan: 8 h per won order, sourcing to shipping.
B35: BRL per USD | C35: 5.2 | D35: The rate implied by the written plan's US$ figures. Check the spot rate before quoting it to anyone.

Sheet DEAL
B2: DEAL — the arithmetic. Nothing on this sheet is typed.
B4: COST PER KIT
B5: Goods at list price (BOM total) | C5: =BOM!$E$22 | D5: Sum of the priced BOM lines.
B6: less supplier discount | C6: =-C5*INPUTS!$C$13
B7: Goods after discount | C7: =C5+C6
B8: Allowance for unpriced BOM lines | C8: =INPUTS!$C$17
B9: Assembly | C9: =IF(INPUTS!$C$5<=INPUTS!$C$20,0,IF(INPUTS!$C$19="","",INPUTS!$C$19)) | D9: 0 when you pack it yourself; the co-packer figure otherwise; blank = unknown.
B10: Freight per kit used | C10: =IF(INPUTS!$C$14<>"",INPUTS!$C$14,IF(FREIGHT!$B$8="","",FREIGHT!$B$8)) | D10: Your override if set, otherwise the measured table for this UF and mode.
B11: Packaging / box / label | C11: =INPUTS!$C$18
B12: TOTAL COST PER KIT | C12: =IF(OR(C9="",C10=""),"",C7+C8+C9+C10+C11) | D12: Blank means a cost leg is unknown — that is a NO BID, not a zero.
B14: THE LOT
B15: Bid price per kit | C15: =INPUTS!$C$6*INPUTS!$C$7
B16: Revenue (lot) | C16: =C15*INPUTS!$C$5
B17: Cost of goods + freight + assembly (lot) | C17: =IF(C12="","",C12*INPUTS!$C$5)
B18: Gross profit (lot) | C18: =IF(C17="","",C16-C17)
B19: Gross margin % | C19: =IF(C18="","",IF(C16=0,0,C18/C16))
B20: Simples Nacional effective rate | C20: =IF(INPUTS!$C$23<=0,0.04,IF(INPUTS!$C$23<=180000,0.04,IF(INPUTS!$C$23<=360000,(INPUTS!$C$23*0.073-5940)/INPUTS!$C$23,IF(INPUTS!$C$23<=720000,(INPUTS!$C$23*0.095-13860)/INPUTS!$C$23,IF(INPUTS!$C$23<=1800000,(INPUTS!$C$23*0.107-22500)/INPUTS!$C$23,IF(INPUTS!$C$23<=3600000,(INPUTS!$C$23*0.143-87300)/INPUTS!$C$23,(INPUTS!$C$23*0.19-378000)/INPUTS!$C$23)))))) | D20: LC 123 Anexo I, alíquota EFETIVA = (RBT12 x nominal - dedução)/RBT12. Cobre as seis faixas até R$4,8M.
B21: Simples tax | C21: =C16*C20
B22: IRRF withheld | C22: =C16*INPUTS!$C$24
B23: Platform fee | C23: =MIN(C16*INPUTS!$C$25,INPUTS!$C$26)+INPUTS!$C$27
B24: NET PROFIT (lot) | C24: =IF(C18="","",C18-C21-C22-C23)
B25: NET MARGIN % | C25: =IF(C24="","",IF(C16=0,0,C24/C16))
B26: Net profit per kit | C26: =IF(C24="","",C24/INPUTS!$C$5)
B28: CASH
B29: Cash you must front before the buyer pays | C29: =IF(C17="","",C17+INPUTS!$C$27) | D29: Goods, freight, assembly and any fixed fee all leave before the empenho pays out.
B30: Days that cash is out | C30: =INPUTS!$C$10 | D30: Conservative: assumes cash leaves on day 0. In practice the supplier is paid nearer day 11, so the true return is higher.
B31: Annualised return on that cash | C31: =IF(OR(C24="",C29=""),"",IF(C29=0,0,C24/C29*365/C30))
B33: WHAT WOULD HAVE TO BE TRUE
B34: Break-even price per kit | C34: =IF(C12="","",(C12+INPUTS!$C$27/INPUTS!$C$5)/(1-C20-INPUTS!$C$24-INPUTS!$C$25)) | D34: Ignores the platform fee cap, so it runs slightly conservative.
B35: Price per kit at your target margin | C35: =IF(C12="","",(C12+INPUTS!$C$27/INPUTS!$C$5)/(1-C20-INPUTS!$C$24-INPUTS!$C$25-INPUTS!$C$29))
B36: …as % of the buyer's estimate | C36: =IF(C35="","",C35/INPUTS!$C$6) | D36: Above ~97% the lot cannot be won at target.
B37: Minimum bid as % of estimate to break even | C37: =IF(C34="","",C34/INPUTS!$C$6)
B38: Max TOTAL cost per kit at your bid, at target | C38: =C15*(1-C20-INPUTS!$C$24-INPUTS!$C$25-INPUTS!$C$29)-INPUTS!$C$27/INPUTS!$C$5
B39: Max GOODS cost per kit at target | C39: =IF(OR(C9="",C10=""),"",C38-C8-C9-C10-C11)
B40: Supplier discount needed to hit target | C40: =IF(OR(C39="",C5=0),"",1-C39/C5) | D40: The number to take into a wholesaler meeting.
B41: Max TOTAL cost per kit at break-even | C41: =C15*(1-C20-INPUTS!$C$24-INPUTS!$C$25)-INPUTS!$C$27/INPUTS!$C$5
B42: Supplier discount needed to break even | C42: =IF(OR(C9="",C10="",C5=0),"",1-(C41-C8-C9-C10-C11)/C5)
B43: Max freight per kit at target (rest of cost fixed) | C43: =IF(C9="","",C38-C7-C8-C9-C11) | D43: Negative = no freight price saves this bid.
B44: Max freight per kit at break-even | C44: =IF(C9="","",C41-C7-C8-C9-C11)
B46: WHAT YOU MAKE — one lot scaled into a year
...

Sheet GATES
B2: GATES — net margin under the two things you do not control
B3: Your target net margin | C3: =INPUTS!$C$29 | D3: Green = clears your target. Amber = makes money but misses it. Red = loses money.
B5: GRID A — supplier discount × freight per kit (at your current bid level)
B6: discount off list ↓ freight per kit → | C6: ="YOUR "&INPUTS!$C$8&" "&INPUTS!$C$9 | D6: ="LTL SP→CE" | E6: ="PAC to BA" | F6: ="PAC to CE/PE/PA" | G6: ="PAC to MA/SE/RN" | H6: ="Zero freight (reference)"
C7: =DEAL!$C$10 | D7: 53.99 | E7: 132.9 | F7: 152.6 | G7: 188.4 | H7: 0
B8: 0 | C8: =IF(OR(DEAL!$C$9="",C$7=""),"",1-((BOM!$E$22*(1-$B8)+INPUTS!$C$17+DEAL!$C$9+C$7+INPUTS!$C$18)+INPUTS!$C$27/INPUTS!$C$5)/DEAL!$C$15-DEAL!$C$20-INPUTS!$C$24-INPUTS!$C$25) | D8: =IF(OR(DEAL!$C$9="",D$7=""),"",1-((BOM!$E$22*(1-$B8)+INPUTS!$C$17+DEAL!$C$9+D$7+INPUTS!$C$18)+INPUTS!$C$27/INPUTS!$C$5)/DEAL!$C$15-DEAL!$C$20-INPUTS!$C$24-INPUTS!$C$25) | E8: =IF(OR(DEAL!$C$9="",E$7=""),"",1-((BOM!$E$22*(1-$B8)+INPUTS!$C$17+DEAL!$C$9+E$7+INPUTS!$C$18)+INPUTS!$C$27/INPUTS!$C$5)/DEAL!$C$15-DEAL!$C$20-INPUTS!$C$24-INPUTS!$C$25) | F8: =IF(OR(DEAL!$C$9="",F$7=""),"",1-((BOM!$E$22*(1-$B8)+INPUTS!$C$17+DEAL!$C$9+F$7+INPUTS!$C$18)+INPUTS!$C$27/INPUTS!$C$5)/DEAL!$C$15-DEAL!$C$20-INPUTS!$C$24-INPUTS!$C$25) | G8: =IF(OR(DEAL!$C$9="",G$7=""),"",1-((BOM!$E$22*(1-$B8)+INPUTS!$C$17+DEAL!$C$9+G$7+INPUTS!$C$18)+INPUTS!$C$27/INPUTS!$C$5)/DEAL!$C$15-DEAL!$C$20-INPUTS!$C$24-INPUTS!$C$25) | H8: =IF(OR(DEAL!$C$9="",H$7=""),"",1-((BOM!$E$22*(1-$B8)+INPUTS!$C$17+DEAL!$C$9+H$7+INPUTS!$C$18)+INPUTS!$C$27/INPUTS!$C$5)/DEAL!$C$15-DEAL!$C$20-INPUTS!$C$24-INPUTS!$C$25)
B9: 0.05 | C9: =IF(OR(DEAL!$C$9="",C$7=""),"",1-((BOM!$E$22*(1-$B9)+INPUTS!$C$17+DEAL!$C$9+C$7+INPUTS!$C$18)+INPUTS!$C$27/INPUTS!$C$5)/DEAL!$C$15-DEAL!$C$20-INPUTS!$C$24-INPUTS!$C$25) | D9: =IF(OR(DEAL!$C$9="",D$7=""),"",1-((BOM!$E$22*(1-$B9)+INPUTS!$C$17+DEAL!$C$9+D$7+INPUTS!$C$18)+INPUTS!$C$27/INPUTS!$C$5)/DEAL!$C$15-DEAL!$C$20-INPUTS!$C$24-INPUTS!$C$25) | E9: =IF(OR(DEAL!$C$9="",E$7=""),"",1-((BOM!$E$22*(1-$B9)+INPUTS!$C$17+DEAL!$C$9+E$7+INPUTS!$C$18)+INPUTS!$C$27/INPUTS!$C$5)/DEAL!$C$15-DEAL!$C$20-INPUTS!$C$24-INPUTS!$C$25) | F9: =IF(OR(DEAL!$C$9="",F$7=""),"",1-((BOM!$E$22*(1-$B9)+INPUTS!$C$17+DEAL!$C$9+F$7+INPUTS!$C$18)+INPUTS!$C$27/INPUTS!$C$5)/DEAL!$C$15-DEAL!$C$20-INPUTS!$C$24-INPUTS!$C$25) | G9: =IF(OR(DEAL!$C$9="",G$7=""),"",1-((BOM!$E$22*(1-$B9)+INPUTS!$C$17+DEAL!$C$9+G$7+INPUTS!$C$18)+INPUTS!$C$27/INPUTS!$C$5)/DEAL!$C$15-DEAL!$C$20-INPUTS!$C$24-INPUTS!$C$25) | H9: =IF(OR(DEAL!$C$9="",H$7=""),"",1-((BOM!$E$22*(1-$B9)+INPUTS!$C$17+DEAL!$C$9+H$7+INPUTS!$C$18)+INPUTS!$C$27/INPUTS!$C$5)/DEAL!$C$15-DEAL!$C$20-INPUTS!$C$24-INPUTS!$C$25)
B10: 0.1 | C10: =IF(OR(DEAL!$C$9="",C$7=""),"",1-((BOM!$E$22*(1-$B10)+INPUTS!$C$17+DEAL!$C$9+C$7+INPUTS!$C$18)+INPUTS!$C$27/INPUTS!$C$5)/DEAL!$C$15-DEAL!$C$20-INPUTS!$C$24-INPUTS!$C$25) | D10: =IF(OR(DEAL!$C$9="",D$7=""),"",1-((BOM!$E$22*(1-$B10)+INPUTS!$C$17+DEAL!$C$9+D$7+INPUTS!$C$18)+INPUTS!$C$27/INPUTS!$C$5)/DEAL!$C$15-DEAL!$C$20-INPUTS!$C$24-INPUTS!$C$25) | E10: =IF(OR(DEAL!$C$9="",E$7=""),"",1-((BOM!$E$22*(1-$B10)+INPUTS!$C$17+DEAL!$C$9+E$7+INPUTS!$C$18)+INPUTS!$C$27/INPUTS!$C$5)/DEAL!$C$15-DEAL!$C$20-INPUTS!$C$24-INPUTS!$C$25) | F10: =IF(OR(DEAL!$C$9="",F$7=""),"",1-((BOM!$E$22*(1-$B10)+INPUTS!$C$17+DEAL!$C$9+F$7+INPUTS!$C$18)+INPUTS!$C$27/INPUTS!$C$5)/DEAL!$C$15-DEAL!$C$20-INPUTS!$C$24-INPUTS!$C$25) | G10: =IF(OR(DEAL!$C$9="",G$7=""),"",1-((BOM!$E$22*(1-$B10)+INPUTS!$C$17+DEAL!$C$9+G$7+INPUTS!$C$18)+INPUTS!$C$27/INPUTS!$C$5)/DEAL!$C$15-DEAL!$C$20-INPUTS!$C$24-INPUTS!$C$25) | H10: =IF(OR(DEAL!$C$9="",H$7=""),"",1-((BOM!$E$22*(1-$B10)+INPUTS!$C$17+DEAL!$C$9+H$7+INPUTS!$C$18)+INPUTS!$C$27/INPUTS!$C$5)/DEAL!$C$15-DEAL!$C$20-INPUTS!$C$24-INPUTS!$C$25)
B11: 0.15 | C11: =IF(OR(DEAL!$C$9="",C$7=""),"",1-((BOM!$E$22*(1-$B11)+INPUTS!$C$17+DEAL!$C$9+C$7+INPUTS!$C$18)+INPUTS!$C$27/INPUTS!$C$5)/DEAL!$C$15-DEAL!$C$20-INPUTS!$C$24-INPUTS!$C$25) | D11: =IF(OR(DEAL!$C$9="",D$7=""),"",1-((BOM!$E$22*(1-$B11)+INPUTS!$C$17+DEAL!$C$9+D$7+INPUTS!$C$18)+INPUTS!$C$27/INPUTS!$C$5)/DEAL!$C$15-DEAL!$C$20-INPUTS!$C$24-INPUTS!$C$25) | E11: =IF(OR(DEAL!$C$9="",E$7=""),"",1-((BOM!$E$22*(1-$B11)+INPUTS!$C$17+DEAL!$C$9+E$7+INPUTS!$C$18)+INPUTS!$C$27/INPUTS!$C$5)/DEAL!$C$15-DEAL!$C$20-INPUTS!$C$24-INPUTS!$C$25) | F11: =IF(OR(DEAL!$C$9="",F$7=""),"",1-((BOM!$E$22*(1-$B11)+INPUTS!$C$17+DEAL!$C$9+F$7+INPUTS!$C$18)+INPUTS!$C$27/INPUTS!$C$5)/DEAL!$C$15-DEAL!$C$20-INPUTS!$C$24-INPUTS!$C$25) | G11: =IF(OR(DEAL!$C$9="",G$7=""),"",1-((BOM!$E$22*(1-$B11)+INPUTS!$C$17+DEAL!$C$9+G$7+INPUTS!$C$18)+INPUTS!$C$27/INPUTS!$C$5)/DEAL!$C$15-DEAL!$C$20-INPUTS!$C$24-INPUTS!$C$25) | H11: =IF(OR(DEAL!$C$9="",H$7=""),"",1-((BOM!$E$22*(1-$B11)+INPUTS!$C$17+DEAL!$C$9+H$7+INPUTS!$C$18)+INPUTS!$C$27/INPUTS!$C$5)/DEAL!$C$15-DEAL!$C$20-INPUTS!$C$24-INPUTS!$C$25)
B12: 0.2 | C12: =IF(OR(DEAL!$C$9="",C$7=""),"",1-((BOM!$E$22*(1-$B12)+INPUTS!$C$17+DEAL!$C$9+C$7+INPUTS!$C$18)+INPUTS!$C$27/INPUTS!$C$5)/DEAL!$C$15-DEAL!$C$20-INPUTS!$C$24-INPUTS!$C$25) | D12: =IF(OR(DEAL!$C$9="",D$7=""),"",1-((BOM!$E$22*(1-$B12)+INPUTS!$C$17+DEAL!$C$9+D$7+INPUTS!$C$18)+INPUTS!$C$27/INPUTS!$C$5)/DEAL!$C$15-DEAL!$C$20-INPUTS!$C$24-INPUTS!$C$25) | E12: =IF(OR(DEAL!$C$9="",E$7=""),"",1-((BOM!$E$22*(1-$B12)+INPUTS!$C$17+DEAL!$C$9+E$7+INPUTS!$C$18)+INPUTS!$C$27/INPUTS!$C$5)/DEAL!$C$15-DEAL!$C$20-INPUTS!$C$24-INPUTS!$C$25) | F12: =IF(OR(DEAL!$C$9="",F$7=""),"",1-((BOM!$E$22*(1-$B12)+INPUTS!$C$17+DEAL!$C$9+F$7+INPUTS!$C$18)+INPUTS!$C$27/INPUTS!$C$5)/DEAL!$C$15-DEAL!$C$20-INPUTS!$C$24-INPUTS!$C$25) | G12: =IF(OR(DEAL!$C$9="",G$7=""),"",1-((BOM!$E$22*(1-$B12)+INPUTS!$C$17+DEAL!$C$9+G$7+INPUTS!$C$18)+INPUTS!$C$27/INPUTS!$C$5)/DEAL!$C$15-DEAL!$C$20-INPUTS!$C$24-INPUTS!$C$25) | H12: =IF(OR(DEAL!$C$9="",H$7=""),"",1-((BOM!$E$22*(1-$B12)+INPUTS!$C$17+DEAL!$C$9+H$7+INPUTS!$C$18)+INPUTS!$C$27/INPUTS!$C$5)/DEAL!$C$15-DEAL!$C$20-INPUTS!$C$24-INPUTS!$C$25)
B13: 0.25 | C13: =IF(OR(DEAL!$C$9="",C$7=""),"",1-((BOM!$E$22*(1-$B13)+INPUTS!$C$17+DEAL!$C$9+C$7+INPUTS!$C$18)+INPUTS!$C$27/INPUTS!$C$5)/DEAL!$C$15-DEAL!$C$20-INPUTS!$C$24-INPUTS!$C$25) | D13: =IF(OR(DEAL!$C$9="",D$7=""),"",1-((BOM!$E$22*(1-$B13)+INPUTS!$C$17+DEAL!$C$9+D$7+INPUTS!$C$18)+INPUTS!$C$27/INPUTS!$C$5)/DEAL!$C$15-DEAL!$C$20-INPUTS!$C$24-INPUTS!$C$25) | E13: =IF(OR(DEAL!$C$9="",E$7=""),"",1-((BOM!$E$22*(1-$B13)+INPUTS!$C$17+DEAL!$C$9+E$7+INPUTS!$C$18)+INPUTS!$C$27/INPUTS!$C$5)/DEAL!$C$15-DEAL!$C$20-INPUTS!$C$24-INPUTS!$C$25) | F13: =IF(OR(DEAL!$C$9="",F$7=""),"",1-((BOM!$E$22*(1-$B13)+INPUTS!$C$17+DEAL!$C$9+F$7+INPUTS!$C$18)+INPUTS!$C$27/INPUTS!$C$5)/DEAL!$C$15-DEAL!$C$20-INPUTS!$C$24-INPUTS!$C$25) | G13: =IF(OR(DEAL!$C$9="",G$7=""),"",1-((BOM!$E$22*(1-$B13)+INPUTS!$C$17+DEAL!$C$9+G$7+INPUTS!$C$18)+INPUTS!$C$27/INPUTS!$C$5)/DEAL!$C$15-DEAL!$C$20-INPUTS!$C$24-INPUTS!$C$25) | H13: =IF(OR(DEAL!$C$9="",H$7=""),"",1-((BOM!$E$22*(1-$B13)+INPUTS!$C$17+DEAL!$C$9+H$7+INPUTS!$C$18)+INPUTS!$C$27/INPUTS!$C$5)/DEAL!$C$15-DEAL!$C$20-INPUTS!$C$24-INPUTS!$C$25)
B14: 0.3 | C14: =IF(OR(DEAL!$C$9="",C$7=""),"",1-((BOM!$E$22*(1-$B14)+INPUTS!$C$17+DEAL!$C$9+C$7+INPUTS!$C$18)+INPUTS!$C$27/INPUTS!$C$5)/DEAL!$C$15-DEAL!$C$20-INPUTS!$C$24-INPUTS!$C$25) | D14: =IF(OR(DEAL!$C$9="",D$7=""),"",1-((BOM!$E$22*(1-$B14)+INPUTS!$C$17+DEAL!$C$9+D$7+INPUTS!$C$18)+INPUTS!$C$27/INPUTS!$C$5)/DEAL!$C$15-DEAL!$C$20-INPUTS!$C$24-INPUTS!$C$25) | E14: =IF(OR(DEAL!$C$9="",E$7=""),"",1-((BOM!$E$22*(1-$B14)+INPUTS!$C$17+DEAL!$C$9+E$7+INPUTS!$C$18)+INPUTS!$C$27/INPUTS!$C$5)/DEAL!$C$15-DEAL!$C$20-INPUTS!$C$24-INPUTS!$C$25) | F14: =IF(OR(DEAL!$C$9="",F$7=""),"",1-((BOM!$E$22*(1-$B14)+INPUTS!$C$17+DEAL!$C$9+F$7+INPUTS!$C$18)+INPUTS!$C$27/INPUTS!$C$5)/DEAL!$C$15-DEAL!$C$20-INPUTS!$C$24-INPUTS!$C$25) | G14: =IF(OR(DEAL!$C$9="",G$7=""),"",1-((BOM!$E$22*(1-$B14)+INPUTS!$C$17+DEAL!$C$9+G$7+INPUTS!$C$18)+INPUTS!$C$27/INPUTS!$C$5)/DEAL!$C$15-DEAL!$C$20-INPUTS!$C$24-INPUTS!$C$25) | H14: =IF(OR(DEAL!$C$9="",H$7=""),"",1-((BOM!$E$22*(1-$B14)+INPUTS!$C$17+DEAL!$C$9+H$7+INPUTS!$C$18)+INPUTS!$C$27/INPUTS!$C$5)/DEAL!$C$15-DEAL!$C$20-INPUTS!$C$24-INPUTS!$C$25)
B15: 0.35 | C15: =IF(OR(DEAL!$C$9="",C$7=""),"",1-((BOM!$E$22*(1-$B15)+INPUTS!$C$17+DEAL!$C$9+C$7+INPUTS!$C$18)+INPUTS!$C$27/INPUTS!$C$5)/DEAL!$C$15-DEAL!$C$20-INPUTS!$C$24-INPUTS!$C$25) | D15: =IF(OR(DEAL!$C$9="",D$7=""),"",1-((BOM!$E$22*(1-$B15)+INPUTS!$C$17+DEAL!$C$9+D$7+INPUTS!$C$18)+INPUTS!$C$27/INPUTS!$C$5)/DEAL!$C$15-DEAL!$C$20-INPUTS!$C$24-INPUTS!$C$25) | E15: =IF(OR(DEAL!$C$9="",E$7=""),"",1-((BOM!$E$22*(1-$B15)+INPUTS!$C$17+DEAL!$C$9+E$7+INPUTS!$C$18)+INPUTS!$C$27/INPUTS!$C$5)/DEAL!$C$15-DEAL!$C$20-INPUTS!$C$24-INPUTS!$C$25) | F15: =IF(OR(DEAL!$C$9="",F$7=""),"",1-((BOM!$E$22*(1-$B15)+INPUTS!$C$17+DEAL!$C$9+F$7+INPUTS!$C$18)+INPUTS!$C$27/INPUTS!$C$5)/DEAL!$C$15-DEAL!$C$20-INPUTS!$C$24-INPUTS!$C$25) | G15: =IF(OR(DEAL!$C$9="",G$7=""),"",1-((BOM!$E$22*(1-$B15)+INPUTS!$C$17+DEAL!$C$9+G$7+INPUTS!$C$18)+INPUTS!$C$27/INPUTS!$C$5)/DEAL!$C$15-DEAL!$C$20-INPUTS!$C$24-INPUTS!$C$25) | H15: =IF(OR(DEAL!$C$9="",H$7=""),"",1-((BOM!$E$22*(1-$B15)+INPUTS!$C$17+DEAL!$C$9+H$7+INPUTS!$C$18)+INPUTS!$C$27/INPUTS!$C$5)/DEAL!$C$15-DEAL!$C$20-INPUTS!$C$24-INPUTS!$C$25)
B16: 0.4 | C16: =IF(OR(DEAL!$C$9="",C$7=""),"",1-((BOM!$E$22*(1-$B16)+INPUTS!$C$17+DEAL!$C$9+C$7+INPUTS!$C$18)+INPUTS!$C$27/INPUTS!$C$5)/DEAL!$C$15-DEAL!$C$20-INPUTS!$C$24-INPUTS!$C$25) | D16: =IF(OR(DEAL!$C$9="",D$7=""),"",1-((BOM!$E$22*(1-$B16)+INPUTS!$C$17+DEAL!$C$9+D$7+INPUTS!$C$18)+INPUTS!$C$27/INPUTS!$C$5)/DEAL!$C$15-DEAL!$C$20-INPUTS!$C$24-INPUTS!$C$25) | E16: =IF(OR(DEAL!$C$9="",E$7=""),"",1-((BOM!$E$22*(1-$B16)+INPUTS!$C$17+DEAL!$C$9+E$7+INPUTS!$C$18)+INPUTS!$C$27/INPUTS!$C$5)/DEAL!$C$15-DEAL!$C$20-INPUTS!$C$24-INPUTS!$C$25) | F16: =IF(OR(DEAL!$C$9="",F$7=""),"",1-((BOM!$E$22*(1-$B16)+INPUTS!$C$17+DEAL!$C$9+F$7+INPUTS!$C$18)+INPUTS!$C$27/INPUTS!$C$5)/DEAL!$C$15-DEAL!$C$20-INPUTS!$C$24-INPUTS!$C$25) | G16: =IF(OR(DEAL!$C$9="",G$7=""),"",1-((BOM!$E$22*(1-$B16)+INPUTS!$C$17+DEAL!$C$9+G$7+INPUTS!$C$18)+INPUTS!$C$27/INPUTS!$C$5)/DEAL!$C$15-DEAL!$C$20-INPUTS!$C$24-INPUTS!$C$25) | H16: =IF(OR(DEAL!$C$9="",H$7=""),"",1-((BOM!$E$22*(1-$B16)+INPUTS!$C$17+DEAL!$C$9+H$7+INPUTS!$C$18)+INPUTS!$C$27/INPUTS!$C$5)/DEAL!$C$15-DEAL!$C$20-INPUTS!$C$24-INPUTS!$C$25)
B17: 0.45 | C17: =IF(OR(DEAL!$C$9="",C$7=""),"",1-((BOM!$E$22*(1-$B17)+INPUTS!$C$17+DEAL!$C$9+C$7+INPUTS!$C$18)+INPUTS!$C$27/INPUTS!$C$5)/DEAL!$C$15-DEAL!$C$20-INPUTS!$C$24-INPUTS!$C$25) | D17: =IF(OR(DEAL!$C$9="",D$7=""),"",1-((BOM!$E$22*(1-$B17)+INPUTS!$C$17+DEAL!$C$9+D$7+INPUTS!$C$18)+INPUTS!$C$27/INPUTS!$C$5)/DEAL!$C$15-DEAL!$C$20-INPUTS!$C$24-INPUTS!$C$25) | E17: =IF(OR(DEAL!$C$9="",E$7=""),"",1-((BOM!$E$22*(1-$B17)+INPUTS!$C$17+DEAL!$C$9+E$7+INPUTS!$C$18)+INPUTS!$C$27/INPUTS!$C$5)/DEAL!$C$15-DEAL!$C$20-INPUTS!$C$24-INPUTS!$C$25) | F17: =IF(OR(DEAL!$C$9="",F$7=""),"",1-((BOM!$E$22*(1-$B17)+INPUTS!$C$17+DEAL!$C$9+F$7+INPUTS!$C$18)+INPUTS!$C$27/INPUTS!$C$5)/DEAL!$C$15-DEAL!$C$20-INPUTS!$C$24-INPUTS!$C$25) | G17: =IF(OR(DEAL!$C$9="",G$7=""),"",1-((BOM!$E$22*(1-$B17)+INPUTS!$C$17+DEAL!$C$9+G$7+INPUTS!$C$18)+INPUTS!$C$27/INPUTS!$C$5)/DEAL!$C$15-DEAL!$C$20-INPUTS!$C$24-INPUTS!$C$25) | H17: =IF(OR(DEAL!$C$9="",H$7=""),"",1-((BOM!$E$22*(1-$B17)+INPUTS!$C$17+DEAL!$C$9+H$7+INPUTS!$C$18)+INPUTS!$C$27/INPUTS!$C$5)/DEAL!$C$15-DEAL!$C$20-INPUTS!$C$24-INPUTS!$C$25)
B18: 0.5 | C18: =IF(OR(DEAL!$C$9="",C$7=""),"",1-((BOM!$E$22*(1-$B18)+INPUTS!$C$17+DEAL!$C$9+C$7+INPUTS!$C$18)+INPUTS!$C$27/INPUTS!$C$5)/DEAL!$C$15-DEAL!$C$20-INPUTS!$C$24-INPUTS!$C$25) | D18: =IF(OR(DEAL!$C$9="",D$7=""),"",1-((BOM!$E$22*(1-$B18)+INPUTS!$C$17+DEAL!$C$9+D$7+INPUTS!$C$18)+INPUTS!$C$27/INPUTS!$C$5)/DEAL!$C$15-DEAL!$C$20-INPUTS!$C$24-INPUTS!$C$25) | E18: =IF(OR(DEAL!$C$9="",E$7=""),"",1-((BOM!$E$22*(1-$B18)+INPUTS!$C$17+DEAL!$C$9+E$7+INPUTS!$C$18)+INPUTS!$C$27/INPUTS!$C$5)/DEAL!$C$15-DEAL!$C$20-INPUTS!$C$24-INPUTS!$C$25) | F18: =IF(OR(DEAL!$C$9="",F$7=""),"",1-((BOM!$E$22*(1-$B18)+INPUTS!$C$17+DEAL!$C$9+F$7+INPUTS!$C$18)+INPUTS!$C$27/INPUTS!$C$5)/DEAL!$C$15-DEAL!$C$20-INPUTS!$C$24-INPUTS!$C$25) | G18: =IF(OR(DEAL!$C$9="",G$7=""),"",1-((BOM!$E$22*(1-$B18)+INPUTS!$C$17+DEAL!$C$9+G$7+INPUTS!$C$18)+INPUTS!$C$27/INPUTS!$C$5)/DEAL!$C$15-DEAL!$C$20-INPUTS!$C$24-INPUTS!$C$25) | H18: =IF(OR(DEAL!$C$9="",H$7=""),"",1-((BOM!$E$22*(1-$B18)+INPUTS!$C$17+DEAL!$C$9+H$7+INPUTS!$C$18)+INPUTS!$C$27/INPUTS!$C$5)/DEAL!$C$15-DEAL!$C$20-INPUTS!$C$24-INPUTS!$C$25)
B20: GRID B — bid as % of estimate × supplier discount (at YOUR freight)
B21: bid % of estimate ↓ discount off list →
C22: 0 | D22: 0.1 | E22: 0.2 | F22: 0.3 | G22: 0.4 | H22: 0.45
B23: 0.6 | C23: =IF(OR(DEAL!$C$9="",DEAL!$C$10=""),"",1-((BOM!$E$22*(1-C$22)+INPUTS!$C$17+DEAL!$C$9+DEAL!$C$10+INPUTS!$C$18)+INPUTS!$C$27/INPUTS!$C$5)/(INPUTS!$C$6*$B23)-DEAL!$C$20-INPUTS!$C$24-INPUTS!$C$25) | D23: =IF(OR(DEAL!$C$9="",DEAL!$C$10=""),"",1-((BOM!$E$22*(1-D$22)+INPUTS!$C$17+DEAL!$C$9+DEAL!$C$10+INPUTS!$C$18)+INPUTS!$C$27/INPUTS!$C$5)/(INPUTS!$C$6*$B23)-DEAL!$C$20-INPUTS!$C$24-INPUTS!$C$25) | E23: =IF(OR(DEAL!$C$9="",DEAL!$C$10=""),"",1-((BOM!$E$22*(1-E$22)+INPUTS!$C$17+DEAL!$C$9+DEAL!$C$10+INPUTS!$C$18)+INPUTS!$C$27/INPUTS!$C$5)/(INPUTS!$C$6*$B23)-DEAL!$C$20-INPUTS!$C$24-INPUTS!$C$25) | F23: =IF(OR(DEAL!$C$9="",DEAL!$C$10=""),"",1-((BOM!$E$22*(1-F$22)+INPUTS!$C$17+DEAL!$C$9+DEAL!$C$10+INPUTS!$C$18)+INPUTS!$C$27/INPUTS!$C$5)/(INPUTS!$C$6*$B23)-DEAL!$C$20-INPUTS!$C$24-INPUTS!$C$25) | G23: =IF(OR(DEAL!$C$9="",DEAL!$C$10=""),"",1-((BOM!$E$22*(1-G$22)+INPUTS!$C$17+DEAL!$C$9+DEAL!$C$10+INPUTS!$C$18)+INPUTS!$C$27/INPUTS!$C$5)/(INPUTS!$C$6*$B23)-DEAL!$C$20-INPUTS!$C$24-INPUTS!$C$25) | H23: =IF(OR(DEAL!$C$9="",DEAL!$C$10=""),"",1-((BOM!$E$22*(1-H$22)+INPUTS!$C$17+DEAL!$C$9+DEAL!$C$10+INPUTS!$C$18)+INPUTS!$C$27/INPUTS!$C$5)/(INPUTS!$C$6*$B23)-DEAL!$C$20-INPUTS!$C$24-INPUTS!$C$25)
B24: 0.65 | C24: =IF(OR(DEAL!$C$9="",DEAL!$C$10=""),"",1-((BOM!$E$22*(1-C$22)+INPUTS!$C$17+DEAL!$C$9+DEAL!$C$10+INPUTS!$C$18)+INPUTS!$C$27/INPUTS!$C$5)/(INPUTS!$C$6*$B24)-DEAL!$C$20-INPUTS!$C$24-INPUTS!$C$25) | D24: =IF(OR(DEAL!$C$9="",DEAL!$C$10=""),"",1-((BOM!$E$22*(1-D$22)+INPUTS!$C$17+DEAL!$C$9+DEAL!$C$10+INPUTS!$C$18)+INPUTS!$C$27/INPUTS!$C$5)/(INPUTS!$C$6*$B24)-DEAL!$C$20-INPUTS!$C$24-INPUTS!$C$25) | E24: =IF(OR(DEAL!$C$9="",DEAL!$C$10=""),"",1-((BOM!$E$22*(1-E$22)+INPUTS!$C$17+DEAL!$C$9+DEAL!$C$10+INPUTS!$C$18)+INPUTS!$C$27/INPUTS!$C$5)/(INPUTS!$C$6*$B24)-DEAL!$C$20-INPUTS!$C$24-INPUTS!$C$25) | F24: =IF(OR(DEAL!$C$9="",DEAL!$C$10=""),"",1-((BOM!$E$22*(1-F$22)+INPUTS!$C$17+DEAL!$C$9+DEAL!$C$10+INPUTS!$C$18)+INPUTS!$C$27/INPUTS!$C$5)/(INPUTS!$C$6*$B24)-DEAL!$C$20-INPUTS!$C$24-INPUTS!$C$25) | G24: =IF(OR(DEAL!$C$9="",DEAL!$C$10=""),"",1-((BOM!$E$22*(1-G$22)+INPUTS!$C$17+DEAL!$C$9+DEAL!$C$10+INPUTS!$C$18)+INPUTS!$C$27/INPUTS!$C$5)/(INPUTS!$C$6*$B24)-DEAL!$C$20-INPUTS!$C$24-INPUTS!$C$25) | H24: =IF(OR(DEAL!$C$9="",DEAL!$C$10=""),"",1-((BOM!$E$22*(1-H$22)+INPUTS!$C$17+DEAL!$C$9+DEAL!$C$10+INPUTS!$C$18)+INPUTS!$C$27/INPUTS!$C$5)/(INPUTS!$C$6*$B24)-DEAL!$C$20-INPUTS!$C$24-INPUTS!$C$25)
B25: 0.7 | C25: =IF(OR(DEAL!$C$9="",DEAL!$C$10=""),"",1-((BOM!$E$22*(1-C$22)+INPUTS!$C$17+DEAL!$C$9+DEAL!$C$10+INPUTS!$C$18)+INPUTS!$C$27/INPUTS!$C$5)/(INPUTS!$C$6*$B25)-DEAL!$C$20-INPUTS!$C$24-INPUTS!$C$25) | D25: =IF(OR(DEAL!$C$9="",DEAL!$C$10=""),"",1-((BOM!$E$22*(1-D$22)+INPUTS!$C$17+DEAL!$C$9+DEAL!$C$10+INPUTS!$C$18)+INPUTS!$C$27/INPUTS!$C$5)/(INPUTS!$C$6*$B25)-DEAL!$C$20-INPUTS!$C$24-INPUTS!$C$25) | E25: =IF(OR(DEAL!$C$9="",DEAL!$C$10=""),"",1-((BOM!$E$22*(1-E$22)+INPUTS!$C$17+DEAL!$C$9+DEAL!$C$10+INPUTS!$C$18)+INPUTS!$C$27/INPUTS!$C$5)/(INPUTS!$C$6*$B25)-DEAL!$C$20-INPUTS!$C$24-INPUTS!$C$25) | F25: =IF(OR(DEAL!$C$9="",DEAL!$C$10=""),"",1-((BOM!$E$22*(1-F$22)+INPUTS!$C$17+DEAL!$C$9+DEAL!$C$10+INPUTS!$C$18)+INPUTS!$C$27/INPUTS!$C$5)/(INPUTS!$C$6*$B25)-DEAL!$C$20-INPUTS!$C$24-INPUTS!$C$25) | G25: =IF(OR(DEAL!$C$9="",DEAL!$C$10=""),"",1-((BOM!$E$22*(1-G$22)+INPUTS!$C$17+DEAL!$C$9+DEAL!$C$10+INPUTS!$C$18)+INPUTS!$C$27/INPUTS!$C$5)/(INPUTS!$C$6*$B25)-DEAL!$C$20-INPUTS!$C$24-INPUTS!$C$25) | H25: =IF(OR(DEAL!$C$9="",DEAL!$C$10=""),"",1-((BOM!$E$22*(1-H$22)+INPUTS!$C$17+DEAL!$C$9+DEAL!$C$10+INPUTS!$C$18)+INPUTS!$C$27/INPUTS!$C$5)/(INPUTS!$C$6*$B25)-DEAL!$C$20-INPUTS!$C$24-INPUTS!$C$25)
B26: 0.75 | C26: =IF(OR(DEAL!$C$9="",DEAL!$C$10=""),"",1-((BOM!$E$22*(1-C$22)+INPUTS!$C$17+DEAL!$C$9+DEAL!$C$10+INPUTS!$C$18)+INPUTS!$C$27/INPUTS!$C$5)/(INPUTS!$C$6*$B26)-DEAL!$C$20-INPUTS!$C$24-INPUTS!$C$25) | D26: =IF(OR(DEAL!$C$9="",DEAL!$C$10=""),"",1-((BOM!$E$22*(1-D$22)+INPUTS!$C$17+DEAL!$C$9+DEAL!$C$10+INPUTS!$C$18)+INPUTS!$C$27/INPUTS!$C$5)/(INPUTS!$C$6*$B26)-DEAL!$C$20-INPUTS!$C$24-INPUTS!$C$25) | E26: =IF(OR(DEAL!$C$9="",DEAL!$C$10=""),"",1-((BOM!$E$22*(1-E$22)+INPUTS!$C$17+DEAL!$C$9+DEAL!$C$10+INPUTS!$C$18)+INPUTS!$C$27/INPUTS!$C$5)/(INPUTS!$C$6*$B26)-DEAL!$C$20-INPUTS!$C$24-INPUTS!$C$25) | F26: =IF(OR(DEAL!$C$9="",DEAL!$C$10=""),"",1-((BOM!$E$22*(1-F$22)+INPUTS!$C$17+DEAL!$C$9+DEAL!$C$10+INPUTS!$C$18)+INPUTS!$C$27/INPUTS!$C$5)/(INPUTS!$C$6*$B26)-DEAL!$C$20-INPUTS!$C$24-INPUTS!$C$25) | G26: =IF(OR(DEAL!$C$9="",DEAL!$C$10=""),"",1-((BOM!$E$22*(1-G$22)+INPUTS!$C$17+DEAL!$C$9+DEAL!$C$10+INPUTS!$C$18)+INPUTS!$C$27/INPUTS!$C$5)/(INPUTS!$C$6*$B26)-DEAL!$C$20-INPUTS!$C$24-INPUTS!$C$25) | H26: =IF(OR(DEAL!$C$9="",DEAL!$C$10=""),"",1-((BOM!$E$22*(1-H$22)+INPUTS!$C$17+DEAL!$C$9+DEAL!$C$10+INPUTS!$C$18)+INPUTS!$C$27/INPUTS!$C$5)/(INPUTS!$C$6*$B26)-DEAL!$C$20-INPUTS!$C$24-INPUTS!$C$25)
B27: 0.8 | C27: =IF(OR(DEAL!$C$9="",DEAL!$C$10=""),"",1-((BOM!$E$22*(1-C$22)+INPUTS!$C$17+DEAL!$C$9+DEAL!$C$10+INPUTS!$C$18)+INPUTS!$C$27/INPUTS!$C$5)/(INPUTS!$C$6*$B27)-DEAL!$C$20-INPUTS!$C$24-INPUTS!$C$25) | D27: =IF(OR(DEAL!$C$9="",DEAL!$C$10=""),"",1-((BOM!$E$22*(1-D$22)+INPUTS!$C$17+DEAL!$C$9+DEAL!$C$10+INPUTS!$C$18)+INPUTS!$C$27/INPUTS!$C$5)/(INPUTS!$C$6*$B27)-DEAL!$C$20-INPUTS!$C$24-INPUTS!$C$25) | E27: =IF(OR(DEAL!$C$9="",DEAL!$C$10=""),"",1-((BOM!$E$22*(1-E$22)+INPUTS!$C$17+DEAL!$C$9+DEAL!$C$10+INPUTS!$C$18)+INPUTS!$C$27/INPUTS!$C$5)/(INPUTS!$C$6*$B27)-DEAL!$C$20-INPUTS!$C$24-INPUTS!$C$25) | F27: =IF(OR(DEAL!$C$9="",DEAL!$C$10=""),"",1-((BOM!$E$22*(1-F$22)+INPUTS!$C$17+DEAL!$C$9+DEAL!$C$10+INPUTS!$C$18)+INPUTS!$C$27/INPUTS!$C$5)/(INPUTS!$C$6*$B27)-DEAL!$C$20-INPUTS!$C$24-INPUTS!$C$25) | G27: =IF(OR(DEAL!$C$9="",DEAL!$C$10=""),"",1-((BOM!$E$22*(1-G$22)+INPUTS!$C$17+DEAL!$C$9+DEAL!$C$10+INPUTS!$C$18)+INPUTS!$C$27/INPUTS!$C$5)/(INPUTS!$C$6*$B27)-DEAL!$C$20-INPUTS!$C$24-INPUTS!$C$25) | H27: =IF(OR(DEAL!$C$9="",DEAL!$C$10=""),"",1-((BOM!$E$22*(1-H$22)+INPUTS!$C$17+DEAL!$C$9+DEAL!$C$10+INPUTS!$C$18)+INPUTS!$C$27/INPUTS!$C$5)/(INPUTS!$C$6*$B27)-DEAL!$C$20-INPUTS!$C$24-INPUTS!$C$25)
B28: 0.85 | C28: =IF(OR(DEAL!$C$9="",DEAL!$C$10=""),"",1-((BOM!$E$22*(1-C$22)+INPUTS!$C$17+DEAL!$C$9+DEAL!$C$10+INPUTS!$C$18)+INPUTS!$C$27/INPUTS!$C$5)/(INPUTS!$C$6*$B28)-DEAL!$C$20-INPUTS!$C$24-INPUTS!$C$25) | D28: =IF(OR(DEAL!$C$9="",DEAL!$C$10=""),"",1-((BOM!$E$22*(1-D$22)+INPUTS!$C$17+DEAL!$C$9+DEAL!$C$10+INPUTS!$C$18)+INPUTS!$C$27/INPUTS!$C$5)/(INPUTS!$C$6*$B28)-DEAL!$C$20-INPUTS!$C$24-INPUTS!$C$25) | E28: =IF(OR(DEAL!$C$9="",DEAL!$C$10=""),"",1-((BOM!$E$22*(1-E$22)+INPUTS!$C$17+DEAL!$C$9+DEAL!$C$10+INPUTS!$C$18)+INPUTS!$C$27/INPUTS!$C$5)/(INPUTS!$C$6*$B28)-DEAL!$C$20-INPUTS!$C$24-INPUTS!$C$25) | F28: =IF(OR(DEAL!$C$9="",DEAL!$C$10=""),"",1-((BOM!$E$22*(1-F$22)+INPUTS!$C$17+DEAL!$C$9+DEAL!$C$10+INPUTS!$C$18)+INPUTS!$C$27/INPUTS!$C$5)/(INPUTS!$C$6*$B28)-DEAL!$C$20-INPUTS!$C$24-INPUTS!$C$25) | G28: =IF(OR(DEAL!$C$9="",DEAL!$C$10=""),"",1-((BOM!$E$22*(1-G$22)+INPUTS!$C$17+DEAL!$C$9+DEAL!$C$10+INPUTS!$C$18)+INPUTS!$C$27/INPUTS!$C$5)/(INPUTS!$C$6*$B28)-DEAL!$C$20-INPUTS!$C$24-INPUTS!$C$25) | H28: =IF(OR(DEAL!$C$9="",DEAL!$C$10=""),"",1-((BOM!$E$22*(1-H$22)+INPUTS!$C$17+DEAL!$C$9+DEAL!$C$10+INPUTS!$C$18)+INPUTS!$C$27/INPUTS!$C$5)/(INPUTS!$C$6*$B28)-DEAL!$C$20-INPUTS!$C$24-INPUTS!$C$25)
B29: 0.9 | C29: =IF(OR(DEAL!$C$9="",DEAL!$C$10=""),"",1-((BOM!$E$22*(1-C$22)+INPUTS!$C$17+DEAL!$C$9+DEAL!$C$10+INPUTS!$C$18)+INPUTS!$C$27/INPUTS!$C$5)/(INPUTS!$C$6*$B29)-DEAL!$C$20-INPUTS!$C$24-INPUTS!$C$25) | D29: =IF(OR(DEAL!$C$9="",DEAL!$C$10=""),"",1-((BOM!$E$22*(1-D$22)+INPUTS!$C$17+DEAL!$C$9+DEAL!$C$10+INPUTS!$C$18)+INPUTS!$C$27/INPUTS!$C$5)/(INPUTS!$C$6*$B29)-DEAL!$C$20-INPUTS!$C$24-INPUTS!$C$25) | E29: =IF(OR(DEAL!$C$9="",DEAL!$C$10=""),"",1-((BOM!$E$22*(1-E$22)+INPUTS!$C$17+DEAL!$C$9+DEAL!$C$10+INPUTS!$C$18)+INPUTS!$C$27/INPUTS!$C$5)/(INPUTS!$C$6*$B29)-DEAL!$C$20-INPUTS!$C$24-INPUTS!$C$25) | F29: =IF(OR(DEAL!$C$9="",DEAL!$C$10=""),"",1-((BOM!$E$22*(1-F$22)+INPUTS!$C$17+DEAL!$C$9+DEAL!$C$10+INPUTS!$C$18)+INPUTS!$C$27/INPUTS!$C$5)/(INPUTS!$C$6*$B29)-DEAL!$C$20-INPUTS!$C$24-INPUTS!$C$25) | G29: =IF(OR(DEAL!$C$9="",DEAL!$C$10=""),"",1-((BOM!$E$22*(1-G$22)+INPUTS!$C$17+DEAL!$C$9+DEAL!$C$10+INPUTS!$C$18)+INPUTS!$C$27/INPUTS!$C$5)/(INPUTS!$C$6*$B29)-DEAL!$C$20-INPUTS!$C$24-INPUTS!$C$25) | H29: =IF(OR(DEAL!$C$9="",DEAL!$C$10=""),"",1-((BOM!$E$22*(1-H$22)+INPUTS!$C$17+DEAL!$C$9+DEAL!$C$10+INPUTS!$C$18)+INPUTS!$C$27/INPUTS!$C$5)/(INPUTS!$C$6*$B29)-DEAL!$C$20-INPUTS!$C$24-INPUTS!$C$25)
B30: 0.95 | C30: =IF(OR(DEAL!$C$9="",DEAL!$C$10=""),"",1-((BOM!$E$22*(1-C$22)+INPUTS!$C$17+DEAL!$C$9+DEAL!$C$10+INPUTS!$C$18)+INPUTS!$C$27/INPUTS!$C$5)/(INPUTS!$C$6*$B30)-DEAL!$C$20-INPUTS!$C$24-INPUTS!$C$25) | D30: =IF(OR(DEAL!$C$9="",DEAL!$C$10=""),"",1-((BOM!$E$22*(1-D$22)+INPUTS!$C$17+DEAL!$C$9+DEAL!$C$10+INPUTS!$C$18)+INPUTS!$C$27/INPUTS!$C$5)/(INPUTS!$C$6*$B30)-DEAL!$C$20-INPUTS!$C$24-INPUTS!$C$25) | E30: =IF(OR(DEAL!$C$9="",DEAL!$C$10=""),"",1-((BOM!$E$22*(1-E$22)+INPUTS!$C$17+DEAL!$C$9+DEAL!$C$10+INPUTS!$C$18)+INPUTS!$C$27/INPUTS!$C$5)/(INPUTS!$C$6*$B30)-DEAL!$C$20-INPUTS!$C$24-INPUTS!$C$25) | F30: =IF(OR(DEAL!$C$9="",DEAL!$C$10=""),"",1-((BOM!$E$22*(1-F$22)+INPUTS!$C$17+DEAL!$C$9+DEAL!$C$10+INPUTS!$C$18)+INPUTS!$C$27/INPUTS!$C$5)/(INPUTS!$C$6*$B30)-DEAL!$C$20-INPUTS!$C$24-INPUTS!$C$25) | G30: =IF(OR(DEAL!$C$9="",DEAL!$C$10=""),"",1-((BOM!$E$22*(1-G$22)+INPUTS!$C$17+DEAL!$C$9+DEAL!$C$10+INPUTS!$C$18)+INPUTS!$C$27/INPUTS!$C$5)/(INPUTS!$C$6*$B30)-DEAL!$C$20-INPUTS!$C$24-INPUTS!$C$25) | H30: =IF(OR(DEAL!$C$9="",DEAL!$C$10=""),"",1-((BOM!$E$22*(1-H$22)+INPUTS!$C$17+DEAL!$C$9+DEAL!$C$10+INPUTS!$C$18)+INPUTS!$C$27/INPUTS!$C$5)/(INPUTS!$C$6*$B30)-DEAL!$C$20-INPUTS!$C$24-INPUTS!$C$25)
B31: 1 | C31: =IF(OR(DEAL!$C$9="",DEAL!$C$10=""),"",1-((BOM!$E$22*(1-C$22)+INPUTS!$C$17+DEAL!$C$9+DEAL!$C$10+INPUTS!$C$18)+INPUTS!$C$27/INPUTS!$C$5)/(INPUTS!$C$6*$B31)-DEAL!$C$20-INPUTS!$C$24-INPUTS!$C$25) | D31: =IF(OR(DEAL!$C$9="",DEAL!$C$10=""),"",1-((BOM!$E$22*(1-D$22)+INPUTS!$C$17+DEAL!$C$9+DEAL!$C$10+INPUTS!$C$18)+INPUTS!$C$27/INPUTS!$C$5)/(INPUTS!$C$6*$B31)-DEAL!$C$20-INPUTS!$C$24-INPUTS!$C$25) | E31: =IF(OR(DEAL!$C$9="",DEAL!$C$10=""),"",1-((BOM!$E$22*(1-E$22)+INPUTS!$C$17+DEAL!$C$9+DEAL!$C$10+INPUTS!$C$18)+INPUTS!$C$27/INPUTS!$C$5)/(INPUTS!$C$6*$B31)-DEAL!$C$20-INPUTS!$C$24-INPUTS!$C$25) | F31: =IF(OR(DEAL!$C$9="",DEAL!$C$10=""),"",1-((BOM!$E$22*(1-F$22)+INPUTS!$C$17+DEAL!$C$9+DEAL!$C$10+INPUTS!$C$18)+INPUTS!$C$27/INPUTS!$C$5)/(INPUTS!$C$6*$B31)-DEAL!$C$20-INPUTS!$C$24-INPUTS!$C$25) | G31: =IF(OR(DEAL!$C$9="",DEAL!$C$10=""),"",1-((BOM!$E$22*(1-G$22)+INPUTS!$C$17+DEAL!$C$9+DEAL!$C$10+INPUTS!$C$18)+INPUTS!$C$27/INPUTS!$C$5)/(INPUTS!$C$6*$B31)-DEAL!$C$20-INPUTS!$C$24-INPUTS!$C$25) | H31: =IF(OR(DEAL!$C$9="",DEAL!$C$10=""),"",1-((BOM!$E$22*(1-H$22)+INPUTS!$C$17+DEAL!$C$9+DEAL!$C$10+INPUTS!$C$18)+INPUTS!$C$27/INPUTS!$C$5)/(INPUTS!$C$6*$B31)-DEAL!$C$20-INPUTS!$C$24-INPUTS!$C$25)
B34: Read it: find the discount you can actually get, then read across to the freight you will actually pay. Grid A holds the bid fixed at your INPUTS level; Grid B holds freight fixed at yours.
B35: Both grids ignore the platform fee cap, so they run slightly conservative on large lots.

Sheet SCENARIOS
B2: SCENARIOS — the same business under six sets of facts
B3: Each column stands alone: the blue cells are its own assumptions, everything below is computed from them. Lots per year is never assumed — it is what R$15.600 of capital can actually turn over at that column's float.
B5: SCENARIO | C5: A · As typed | D5: B · TODAY, done right | E5: C · + 20% supplier discount | F5: D · + 28-day supplier terms | G5: E · Terms, NO discount | H5: F · Lote único at 50% | I5: WHAT IT MEANS
B6: Kits in the lot | C6: 100 | D6: 61 | E6: 73 | F6: 73 | G6: 61 | H6: 61 | I6: Column A is 100 kits because that is the median tender; B–E are the biggest lot R$15.600 can actually fund.
B7: Bid as % of the buyer's estimate | C7: 0.75 | D7: 0.9 | E7: 0.9 | F7: 0.9 | G7: 0.9 | H7: 0.5 | I7: Per-item lots clear at 97–100% of estimate. Bidding 75% was never required — it was inherited.
B8: Supplier discount off list | C8: 0 | D8: 0 | E8: 0.2 | F8: 0.2 | G8: 0 | H8: 0 | I8: UNVERIFIED. ~45% is the rumoured account tier; 20% is deliberately conservative.
B9: Freight per kit (LTL SP→CE, measured) | C9: 53.99 | D9: 53.99 | E9: 53.99 | F9: 53.99 | G9: 53.99 | H9: 53.99 | I9: Swap this for R$188,40 (PAC to MA) and every column below turns negative.
B10: Days the cash is out (float) | C10: 45 | D10: 45 | E10: 45 | F10: 6 | G10: 6 | H10: 45 | I10: 45 = prepay. 6 = a supplier granting 28 days. This one line is the whole business.
B12: Shared by every column: estimate R$359,05 · capital R$15.600 · fixed costs R$6.000/yr · 8 h per order · R$5,20/US$
B14: ONE LOT
B15: Cost per kit | C15: =(BOM!$E$22*(1-C8)+C9) | D15: =(BOM!$E$22*(1-D8)+D9) | E15: =(BOM!$E$22*(1-E8)+E9) | F15: =(BOM!$E$22*(1-F8)+F9) | G15: =(BOM!$E$22*(1-G8)+G9) | H15: =(BOM!$E$22*(1-H8)+H9) | I15: Goods after discount, plus freight. Assembly is R$0 — every lot here is inside the 240-kit self-pack ceiling.
B16: Bid price per kit | C16: =(INPUTS!$C$6*C7) | D16: =(INPUTS!$C$6*D7) | E16: =(INPUTS!$C$6*E7) | F16: =(INPUTS!$C$6*F7) | G16: =(INPUTS!$C$6*G7) | H16: =(INPUTS!$C$6*H7)
B17: Cash you must front | C17: =((BOM!$E$22*(1-C8)+C9)*C6) | D17: =((BOM!$E$22*(1-D8)+D9)*D6) | E17: =((BOM!$E$22*(1-E8)+E9)*E6) | F17: =((BOM!$E$22*(1-F8)+F9)*F6) | G17: =((BOM!$E$22*(1-G8)+G9)*G6) | H17: =((BOM!$E$22*(1-H8)+H9)*H6) | I17: Must not exceed R$15.600. That ceiling is what sets the lot size.
B18: Net margin on the lot | C18: =IF(((INPUTS!$C$6*C7)*C6)=0,0,(((INPUTS!$C$6*C7)*C6)-((BOM!$E$22*(1-C8)+C9)*C6)-((INPUTS!$C$6*C7)*C6)*(IF((((INPUTS!$C$6*C7)*C6)*((INPUTS!$C$28/((BOM!$E$22*(1-C8)+C9)*C6))*365/C10))<=0,0.04,IF((((INPUTS!$C$6*C7)*C6)*((INPUTS!$C$28/((BOM!$E$22*(1-C8)+C9)*C6))*365/C10))<=180000,0.04,IF((((INPUTS!$C$6*C7)*C6)*((INPUTS!$C$28/((BOM!$E$22*(1-C8)+C9)*C6))*365/C10))<=360000,((((INPUTS!$C$6*C7)*C6)*((INPUTS!$C$28/((BOM!$E$22*(1-C8)+C9)*C6))*365/C10))*0.073-5940)/(((INPUTS!$C$6*C7)*C6)*((INPUTS!$C$28/((BOM!$E$22*(1-C8)+C9)*C6))*365/C10)),IF((((INPUTS!$C$6*C7)*C6)*((INPUTS!$C$28/((BOM!$E$22*(1-C8)+C9)*C6))*365/C10))<=720000,((((INPUTS!$C$6*C7)*C6)*((INPUTS!$C$28/((BOM!$E$22*(1-C8)+C9)*C6))*365/C10))*0.095-13860)/(((INPUTS!$C$6*C7)*C6)*((INPUTS!$C$28/((BOM!$E$22*(1-C8)+C9)*C6))*365/C10)),IF((((INPUTS!$C$6*C7)*C6)*((INPUTS!$C$28/((BOM!$E$22*(1-C8)+C9)*C6))*365/C10))<=1800000,((((INPUTS!$C$6*C7)*C6)*((INPUTS!$C$28/((BOM!$E$22*(1-C8)+C9)*C6))*365/C10))*0.107-22500)/(((INPUTS!$C$6*C7)*C6)*((INPUTS!$C$28/((BOM!$E$22*(1-C8)+C9)*C6))*365/C10)),IF((((INPUTS!$C$6*C7)*C6)*((INPUTS!$C$28/((BOM!$E$22*(1-C8)+C9)*C6))*365/C10))<=3600000,((((INPUTS!$C$6*C7)*C6)*((INPUTS!$C$28/((BOM!$E$22*(1-C8)+C9)*C6))*365/C10))*0.143-87300)/(((INPUTS!$C$6*C7)*C6)*((INPUTS!$C$28/((BOM!$E$22*(1-C8)+C9)*C6))*365/C10)),((((INPUTS!$C$6*C7)*C6)*((INPUTS!$C$28/((BOM!$E$22*(1-C8)+C9)*C6))*365/C10))*0.19-378000)/(((INPUTS!$C$6*C7)*C6)*((INPUTS!$C$28/((BOM!$E$22*(1-C8)+C9)*C6))*365/C10)))))))))-MIN(((INPUTS!$C$6*C7)*C6)*INPUTS!$C$25,INPUTS!$C$26))/((INPUTS!$C$6*C7)*C6)) | D18: =IF(((INPUTS!$C$6*D7)*D6)=0,0,(((INPUTS!$C$6*D7)*D6)-((BOM!$E$22*(1-D8)+D9)*D6)-((INPUTS!$C$6*D7)*D6)*(IF((((INPUTS!$C$6*D7)*D6)*((INPUTS!$C$28/((BOM!$E$22*(1-D8)+D9)*D6))*365/D10))<=0,0.04,IF((((INPUTS!$C$6*D7)*D6)*((INPUTS!$C$28/((BOM!$E$22*(1-D8)+D9)*D6))*365/D10))<=180000,0.04,IF((((INPUTS!$C$6*D7)*D6)*((INPUTS!$C$28/((BOM!$E$22*(1-D8)+D9)*D6))*365/D10))<=360000,((((INPUTS!$C$6*D7)*D6)*((INPUTS!$C$28/((BOM!$E$22*(1-D8)+D9)*D6))*365/D10))*0.073-5940)/(((INPUTS!$C$6*D7)*D6)*((INPUTS!$C$28/((BOM!$E$22*(1-D8)+D9)*D6))*365/D10)),IF((((INPUTS!$C$6*D7)*D6)*((INPUTS!$C$28/((BOM!$E$22*(1-D8)+D9)*D6))*365/D10))<=720000,((((INPUTS!$C$6*D7)*D6)*((INPUTS!$C$28/((BOM!$E$22*(1-D8)+D9)*D6))*365/D10))*0.095-13860)/(((INPUTS!$C$6*D7)*D6)*((INPUTS!$C$28/((BOM!$E$22*(1-D8)+D9)*D6))*365/D10)),IF((((INPUTS!$C$6*D7)*D6)*((INPUTS!$C$28/((BOM!$E$22*(1-D8)+D9)*D6))*365/D10))<=1800000,((((INPUTS!$C$6*D7)*D6)*((INPUTS!$C$28/((BOM!$E$22*(1-D8)+D9)*D6))*365/D10))*0.107-22500)/(((INPUTS!$C$6*D7)*D6)*((INPUTS!$C$28/((BOM!$E$22*(1-D8)+D9)*D6))*365/D10)),IF((((INPUTS!$C$6*D7)*D6)*((INPUTS!$C$28/((BOM!$E$22*(1-D8)+D9)*D6))*365/D10))<=3600000,((((INPUTS!$C$6*D7)*D6)*((INPUTS!$C$28/((BOM!$E$22*(1-D8)+D9)*D6))*365/D10))*0.143-87300)/(((INPUTS!$C$6*D7)*D6)*((INPUTS!$C$28/((BOM!$E$22*(1-D8)+D9)*D6))*365/D10)),((((INPUTS!$C$6*D7)*D6)*((INPUTS!$C$28/((BOM!$E$22*(1-D8)+D9)*D6))*365/D10))*0.19-378000)/(((INPUTS!$C$6*D7)*D6)*((INPUTS!$C$28/((BOM!$E$22*(1-D8)+D9)*D6))*365/D10)))))))))-MIN(((INPUTS!$C$6*D7)*D6)*INPUTS!$C$25,INPUTS!$C$26))/((INPUTS!$C$6*D7)*D6)) | E18: =IF(((INPUTS!$C$6*E7)*E6)=0,0,(((INPUTS!$C$6*E7)*E6)-((BOM!$E$22*(1-E8)+E9)*E6)-((INPUTS!$C$6*E7)*E6)*(IF((((INPUTS!$C$6*E7)*E6)*((INPUTS!$C$28/((BOM!$E$22*(1-E8)+E9)*E6))*365/E10))<=0,0.04,IF((((INPUTS!$C$6*E7)*E6)*((INPUTS!$C$28/((BOM!$E$22*(1-E8)+E9)*E6))*365/E10))<=180000,0.04,IF((((INPUTS!$C$6*E7)*E6)*((INPUTS!$C$28/((BOM!$E$22*(1-E8)+E9)*E6))*365/E10))<=360000,((((INPUTS!$C$6*E7)*E6)*((INPUTS!$C$28/((BOM!$E$22*(1-E8)+E9)*E6))*365/E10))*0.073-5940)/(((INPUTS!$C$6*E7)*E6)*((INPUTS!$C$28/((BOM!$E$22*(1-E8)+E9)*E6))*365/E10)),IF((((INPUTS!$C$6*E7)*E6)*((INPUTS!$C$28/((BOM!$E$22*(1-E8)+E9)*E6))*365/E10))<=720000,((((INPUTS!$C$6*E7)*E6)*((INPUTS!$C$28/((BOM!$E$22*(1-E8)+E9)*E6))*365/E10))*0.095-13860)/(((INPUTS!$C$6*E7)*E6)*((INPUTS!$C$28/((BOM!$E$22*(1-E8)+E9)*E6))*365/E10)),IF((((INPUTS!$C$6*E7)*E6)*((INPUTS!$C$28/((BOM!$E$22*(1-E8)+E9)*E6))*365/E10))<=1800000,((((INPUTS!$C$6*E7)*E6)*((INPUTS!$C$28/((BOM!$E$22*(1-E8)+E9)*E6))*365/E10))*0.107-22500)/(((INPUTS!$C$6*E7)*E6)*((INPUTS!$C$28/((BOM!$E$22*(1-E8)+E9)*E6))*365/E10)),IF((((INPUTS!$C$6*E7)*E6)*((INPUTS!$C$28/((BOM!$E$22*(1-E8)+E9)*E6))*365/E10))<=3600000,((((INPUTS!$C$6*E7)*E6)*((INPUTS!$C$28/((BOM!$E$22*(1-E8)+E9)*E6))*365/E10))*0.143-87300)/(((INPUTS!$C$6*E7)*E6)*((INPUTS!$C$28/((BOM!$E$22*(1-E8)+E9)*E6))*365/E10)),((((INPUTS!$C$6*E7)*E6)*((INPUTS!$C$28/((BOM!$E$22*(1-E8)+E9)*E6))*365/E10))*0.19-378000)/(((INPUTS!$C$6*E7)*E6)*((INPUTS!$C$28/((BOM!$E$22*(1-E8)+E9)*E6))*365/E10)))))))))-MIN(((INPUTS!$C$6*E7)*E6)*INPUTS!$C$25,INPUTS!$C$26))/((INPUTS!$C$6*E7)*E6)) | F18: =IF(((INPUTS!$C$6*F7)*F6)=0,0,(((INPUTS!$C$6*F7)*F6)-((BOM!$E$22*(1-F8)+F9)*F6)-((INPUTS!$C$6*F7)*F6)*(IF((((INPUTS!$C$6*F7)*F6)*((INPUTS!$C$28/((BOM!$E$22*(1-F8)+F9)*F6))*365/F10))<=0,0.04,IF((((INPUTS!$C$6*F7)*F6)*((INPUTS!$C$28/((BOM!$E$22*(1-F8)+F9)*F6))*365/F10))<=180000,0.04,IF((((INPUTS!$C$6*F7)*F6)*((INPUTS!$C$28/((BOM!$E$22*(1-F8)+F9)*F6))*365/F10))<=360000,((((INPUTS!$C$6*F7)*F6)*((INPUTS!$C$28/((BOM!$E$22*(1-F8)+F9)*F6))*365/F10))*0.073-5940)/(((INPUTS!$C$6*F7)*F6)*((INPUTS!$C$28/((BOM!$E$22*(1-F8)+F9)*F6))*365/F10)),IF((((INPUTS!$C$6*F7)*F6)*((INPUTS!$C$28/((BOM!$E$22*(1-F8)+F9)*F6))*365/F10))<=720000,((((INPUTS!$C$6*F7)*F6)*((INPUTS!$C$28/((BOM!$E$22*(1-F8)+F9)*F6))*365/F10))*0.095-13860)/(((INPUTS!$C$6*F7)*F6)*((INPUTS!$C$28/((BOM!$E$22*(1-F8)+F9)*F6))*365/F10)),IF((((INPUTS!$C$6*F7)*F6)*((INPUTS!$C$28/((BOM!$E$22*(1-F8)+F9)*F6))*365/F10))<=1800000,((((INPUTS!$C$6*F7)*F6)*((INPUTS!$C$28/((BOM!$E$22*(1-F8)+F9)*F6))*365/F10))*0.107-22500)/(((INPUTS!$C$6*F7)*F6)*((INPUTS!$C$28/((BOM!$E$22*(1-F8)+F9)*F6))*365/F10)),IF((((INPUTS!$C$6*F7)*F6)*((INPUTS!$C$28/((BOM!$E$22*(1-F8)+F9)*F6))*365/F10))<=3600000,((((INPUTS!$C$6*F7)*F6)*((INPUTS!$C$28/((BOM!$E$22*(1-F8)+F9)*F6))*365/F10))*0.143-87300)/(((INPUTS!$C$6*F7)*F6)*((INPUTS!$C$28/((BOM!$E$22*(1-F8)+F9)*F6))*365/F10)),((((INPUTS!$C$6*F7)*F6)*((INPUTS!$C$28/((BOM!$E$22*(1-F8)+F9)*F6))*365/F10))*0.19-378000)/(((INPUTS!$C$6*F7)*F6)*((INPUTS!$C$28/((BOM!$E$22*(1-F8)+F9)*F6))*365/F10)))))))))-MIN(((INPUTS!$C$6*F7)*F6)*INPUTS!$C$25,INPUTS!$C$26))/((INPUTS!$C$6*F7)*F6)) | G18: =IF(((INPUTS!$C$6*G7)*G6)=0,0,(((INPUTS!$C$6*G7)*G6)-((BOM!$E$22*(1-G8)+G9)*G6)-((INPUTS!$C$6*G7)*G6)*(IF((((INPUTS!$C$6*G7)*G6)*((INPUTS!$C$28/((BOM!$E$22*(1-G8)+G9)*G6))*365/G10))<=0,0.04,IF((((INPUTS!$C$6*G7)*G6)*((INPUTS!$C$28/((BOM!$E$22*(1-G8)+G9)*G6))*365/G10))<=180000,0.04,IF((((INPUTS!$C$6*G7)*G6)*((INPUTS!$C$28/((BOM!$E$22*(1-G8)+G9)*G6))*365/G10))<=360000,((((INPUTS!$C$6*G7)*G6)*((INPUTS!$C$28/((BOM!$E$22*(1-G8)+G9)*G6))*365/G10))*0.073-5940)/(((INPUTS!$C$6*G7)*G6)*((INPUTS!$C$28/((BOM!$E$22*(1-G8)+G9)*G6))*365/G10)),IF((((INPUTS!$C$6*G7)*G6)*((INPUTS!$C$28/((BOM!$E$22*(1-G8)+G9)*G6))*365/G10))<=720000,((((INPUTS!$C$6*G7)*G6)*((INPUTS!$C$28/((BOM!$E$22*(1-G8)+G9)*G6))*365/G10))*0.095-13860)/(((INPUTS!$C$6*G7)*G6)*((INPUTS!$C$28/((BOM!$E$22*(1-G8)+G9)*G6))*365/G10)),IF((((INPUTS!$C$6*G7)*G6)*((INPUTS!$C$28/((BOM!$E$22*(1-G8)+G9)*G6))*365/G10))<=1800000,((((INPUTS!$C$6*G7)*G6)*((INPUTS!$C$28/((BOM!$E$22*(1-G8)+G9)*G6))*365/G10))*0.107-22500)/(((INPUTS!$C$6*G7)*G6)*((INPUTS!$C$28/((BOM!$E$22*(1-G8)+G9)*G6))*365/G10)),IF((((INPUTS!$C$6*G7)*G6)*((INPUTS!$C$28/((BOM!$E$22*(1-G8)+G9)*G6))*365/G10))<=3600000,((((INPUTS!$C$6*G7)*G6)*((INPUTS!$C$28/((BOM!$E$22*(1-G8)+G9)*G6))*365/G10))*0.143-87300)/(((INPUTS!$C$6*G7)*G6)*((INPUTS!$C$28/((BOM!$E$22*(1-G8)+G9)*G6))*365/G10)),((((INPUTS!$C$6*G7)*G6)*((INPUTS!$C$28/((BOM!$E$22*(1-G8)+G9)*G6))*365/G10))*0.19-378000)/(((INPUTS!$C$6*G7)*G6)*((INPUTS!$C$28/((BOM!$E$22*(1-G8)+G9)*G6))*365/G10)))))))))-MIN(((INPUTS!$C$6*G7)*G6)*INPUTS!$C$25,INPUTS!$C$26))/((INPUTS!$C$6*G7)*G6)) | H18: =IF(((INPUTS!$C$6*H7)*H6)=0,0,(((INPUTS!$C$6*H7)*H6)-((BOM!$E$22*(1-H8)+H9)*H6)-((INPUTS!$C$6*H7)*H6)*(IF((((INPUTS!$C$6*H7)*H6)*((INPUTS!$C$28/((BOM!$E$22*(1-H8)+H9)*H6))*365/H10))<=0,0.04,IF((((INPUTS!$C$6*H7)*H6)*((INPUTS!$C$28/((BOM!$E$22*(1-H8)+H9)*H6))*365/H10))<=180000,0.04,IF((((INPUTS!$C$6*H7)*H6)*((INPUTS!$C$28/((BOM!$E$22*(1-H8)+H9)*H6))*365/H10))<=360000,((((INPUTS!$C$6*H7)*H6)*((INPUTS!$C$28/((BOM!$E$22*(1-H8)+H9)*H6))*365/H10))*0.073-5940)/(((INPUTS!$C$6*H7)*H6)*((INPUTS!$C$28/((BOM!$E$22*(1-H8)+H9)*H6))*365/H10)),IF((((INPUTS!$C$6*H7)*H6)*((INPUTS!$C$28/((BOM!$E$22*(1-H8)+H9)*H6))*365/H10))<=720000,((((INPUTS!$C$6*H7)*H6)*((INPUTS!$C$28/((BOM!$E$22*(1-H8)+H9)*H6))*365/H10))*0.095-13860)/(((INPUTS!$C$6*H7)*H6)*((INPUTS!$C$28/((BOM!$E$22*(1-H8)+H9)*H6))*365/H10)),IF((((INPUTS!$C$6*H7)*H6)*((INPUTS!$C$28/((BOM!$E$22*(1-H8)+H9)*H6))*365/H10))<=1800000,((((INPUTS!$C$6*H7)*H6)*((INPUTS!$C$28/((BOM!$E$22*(1-H8)+H9)*H6))*365/H10))*0.107-22500)/(((INPUTS!$C$6*H7)*H6)*((INPUTS!$C$28/((BOM!$E$22*(1-H8)+H9)*H6))*365/H10)),IF((((INPUTS!$C$6*H7)*H6)*((INPUTS!$C$28/((BOM!$E$22*(1-H8)+H9)*H6))*365/H10))<=3600000,((((INPUTS!$C$6*H7)*H6)*((INPUTS!$C$28/((BOM!$E$22*(1-H8)+H9)*H6))*365/H10))*0.143-87300)/(((INPUTS!$C$6*H7)*H6)*((INPUTS!$C$28/((BOM!$E$22*(1-H8)+H9)*H6))*365/H10)),((((INPUTS!$C$6*H7)*H6)*((INPUTS!$C$28/((BOM!$E$22*(1-H8)+H9)*H6))*365/H10))*0.19-378000)/(((INPUTS!$C$6*H7)*H6)*((INPUTS!$C$28/((BOM!$E$22*(1-H8)+H9)*H6))*365/H10)))))))))-MIN(((INPUTS!$C$6*H7)*H6)*INPUTS!$C$25,INPUTS!$C$26))/((INPUTS!$C$6*H7)*H6))
B19: Net profit on the lot | C19: =(((INPUTS!$C$6*C7)*C6)-((BOM!$E$22*(1-C8)+C9)*C6)-((INPUTS!$C$6*C7)*C6)*(IF((((INPUTS!$C$6*C7)*C6)*((INPUTS!$C$28/((BOM!$E$22*(1-C8)+C9)*C6))*365/C10))<=0,0.04,IF((((INPUTS!$C$6*C7)*C6)*((INPUTS!$C$28/((BOM!$E$22*(1-C8)+C9)*C6))*365/C10))<=180000,0.04,IF((((INPUTS!$C$6*C7)*C6)*((INPUTS!$C$28/((BOM!$E$22*(1-C8)+C9)*C6))*365/C10))<=360000,((((INPUTS!$C$6*C7)*C6)*((INPUTS!$C$28/((BOM!$E$22*(1-C8)+C9)*C6))*365/C10))*0.073-5940)/(((INPUTS!$C$6*C7)*C6)*((INPUTS!$C$28/((BOM!$E$22*(1-C8)+C9)*C6))*365/C10)),IF((((INPUTS!$C$6*C7)*C6)*((INPUTS!$C$28/((BOM!$E$22*(1-C8)+C9)*C6))*365/C10))<=720000,((((INPUTS!$C$6*C7)*C6)*((INPUTS!$C$28/((BOM!$E$22*(1-C8)+C9)*C6))*365/C10))*0.095-13860)/(((INPUTS!$C$6*C7)*C6)*((INPUTS!$C$28/((BOM!$E$22*(1-C8)+C9)*C6))*365/C10)),IF((((INPUTS!$C$6*C7)*C6)*((INPUTS!$C$28/((BOM!$E$22*(1-C8)+C9)*C6))*365/C10))<=1800000,((((INPUTS!$C$6*C7)*C6)*((INPUTS!$C$28/((BOM!$E$22*(1-C8)+C9)*C6))*365/C10))*0.107-22500)/(((INPUTS!$C$6*C7)*C6)*((INPUTS!$C$28/((BOM!$E$22*(1-C8)+C9)*C6))*365/C10)),IF((((INPUTS!$C$6*C7)*C6)*((INPUTS!$C$28/((BOM!$E$22*(1-C8)+C9)*C6))*365/C10))<=3600000,((((INPUTS!$C$6*C7)*C6)*((INPUTS!$C$28/((BOM!$E$22*(1-C8)+C9)*C6))*365/C10))*0.143-87300)/(((INPUTS!$C$6*C7)*C6)*((INPUTS!$C$28/((BOM!$E$22*(1-C8)+C9)*C6))*365/C10)),((((INPUTS!$C$6*C7)*C6)*((INPUTS!$C$28/((BOM!$E$22*(1-C8)+C9)*C6))*365/C10))*0.19-378000)/(((INPUTS!$C$6*C7)*C6)*((INPUTS!$C$28/((BOM!$E$22*(1-C8)+C9)*C6))*365/C10)))))))))-MIN(((INPUTS!$C$6*C7)*C6)*INPUTS!$C$25,INPUTS!$C$26)) | D19: =(((INPUTS!$C$6*D7)*D6)-((BOM!$E$22*(1-D8)+D9)*D6)-((INPUTS!$C$6*D7)*D6)*(IF((((INPUTS!$C$6*D7)*D6)*((INPUTS!$C$28/((BOM!$E$22*(1-D8)+D9)*D6))*365/D10))<=0,0.04,IF((((INPUTS!$C$6*D7)*D6)*((INPUTS!$C$28/((BOM!$E$22*(1-D8)+D9)*D6))*365/D10))<=180000,0.04,IF((((INPUTS!$C$6*D7)*D6)*((INPUTS!$C$28/((BOM!$E$22*(1-D8)+D9)*D6))*365/D10))<=360000,((((INPUTS!$C$6*D7)*D6)*((INPUTS!$C$28/((BOM!$E$22*(1-D8)+D9)*D6))*365/D10))*0.073-5940)/(((INPUTS!$C$6*D7)*D6)*((INPUTS!$C$28/((BOM!$E$22*(1-D8)+D9)*D6))*365/D10)),IF((((INPUTS!$C$6*D7)*D6)*((INPUTS!$C$28/((BOM!$E$22*(1-D8)+D9)*D6))*365/D10))<=720000,((((INPUTS!$C$6*D7)*D6)*((INPUTS!$C$28/((BOM!$E$22*(1-D8)+D9)*D6))*365/D10))*0.095-13860)/(((INPUTS!$C$6*D7)*D6)*((INPUTS!$C$28/((BOM!$E$22*(1-D8)+D9)*D6))*365/D10)),IF((((INPUTS!$C$6*D7)*D6)*((INPUTS!$C$28/((BOM!$E$22*(1-D8)+D9)*D6))*365/D10))<=1800000,((((INPUTS!$C$6*D7)*D6)*((INPUTS!$C$28/((BOM!$E$22*(1-D8)+D9)*D6))*365/D10))*0.107-22500)/(((INPUTS!$C$6*D7)*D6)*((INPUTS!$C$28/((BOM!$E$22*(1-D8)+D9)*D6))*365/D10)),IF((((INPUTS!$C$6*D7)*D6)*((INPUTS!$C$28/((BOM!$E$22*(1-D8)+D9)*D6))*365/D10))<=3600000,((((INPUTS!$C$6*D7)*D6)*((INPUTS!$C$28/((BOM!$E$22*(1-D8)+D9)*D6))*365/D10))*0.143-87300)/(((INPUTS!$C$6*D7)*D6)*((INPUTS!$C$28/((BOM!$E$22*(1-D8)+D9)*D6))*365/D10)),((((INPUTS!$C$6*D7)*D6)*((INPUTS!$C$28/((BOM!$E$22*(1-D8)+D9)*D6))*365/D10))*0.19-378000)/(((INPUTS!$C$6*D7)*D6)*((INPUTS!$C$28/((BOM!$E$22*(1-D8)+D9)*D6))*365/D10)))))))))-MIN(((INPUTS!$C$6*D7)*D6)*INPUTS!$C$25,INPUTS!$C$26)) | E19: =(((INPUTS!$C$6*E7)*E6)-((BOM!$E$22*(1-E8)+E9)*E6)-((INPUTS!$C$6*E7)*E6)*(IF((((INPUTS!$C$6*E7)*E6)*((INPUTS!$C$28/((BOM!$E$22*(1-E8)+E9)*E6))*365/E10))<=0,0.04,IF((((INPUTS!$C$6*E7)*E6)*((INPUTS!$C$28/((BOM!$E$22*(1-E8)+E9)*E6))*365/E10))<=180000,0.04,IF((((INPUTS!$C$6*E7)*E6)*((INPUTS!$C$28/((BOM!$E$22*(1-E8)+E9)*E6))*365/E10))<=360000,((((INPUTS!$C$6*E7)*E6)*((INPUTS!$C$28/((BOM!$E$22*(1-E8)+E9)*E6))*365/E10))*0.073-5940)/(((INPUTS!$C$6*E7)*E6)*((INPUTS!$C$28/((BOM!$E$22*(1-E8)+E9)*E6))*365/E10)),IF((((INPUTS!$C$6*E7)*E6)*((INPUTS!$C$28/((BOM!$E$22*(1-E8)+E9)*E6))*365/E10))<=720000,((((INPUTS!$C$6*E7)*E6)*((INPUTS!$C$28/((BOM!$E$22*(1-E8)+E9)*E6))*365/E10))*0.095-13860)/(((INPUTS!$C$6*E7)*E6)*((INPUTS!$C$28/((BOM!$E$22*(1-E8)+E9)*E6))*365/E10)),IF((((INPUTS!$C$6*E7)*E6)*((INPUTS!$C$28/((BOM!$E$22*(1-E8)+E9)*E6))*365/E10))<=1800000,((((INPUTS!$C$6*E7)*E6)*((INPUTS!$C$28/((BOM!$E$22*(1-E8)+E9)*E6))*365/E10))*0.107-22500)/(((INPUTS!$C$6*E7)*E6)*((INPUTS!$C$28/((BOM!$E$22*(1-E8)+E9)*E6))*365/E10)),IF((((INPUTS!$C$6*E7)*E6)*((INPUTS!$C$28/((BOM!$E$22*(1-E8)+E9)*E6))*365/E10))<=3600000,((((INPUTS!$C$6*E7)*E6)*((INPUTS!$C$28/((BOM!$E$22*(1-E8)+E9)*E6))*365/E10))*0.143-87300)/(((INPUTS!$C$6*E7)*E6)*((INPUTS!$C$28/((BOM!$E$22*(1-E8)+E9)*E6))*365/E10)),((((INPUTS!$C$6*E7)*E6)*((INPUTS!$C$28/((BOM!$E$22*(1-E8)+E9)*E6))*365/E10))*0.19-378000)/(((INPUTS!$C$6*E7)*E6)*((INPUTS!$C$28/((BOM!$E$22*(1-E8)+E9)*E6))*365/E10)))))))))-MIN(((INPUTS!$C$6*E7)*E6)*INPUTS!$C$25,INPUTS!$C$26)) | F19: =(((INPUTS!$C$6*F7)*F6)-((BOM!$E$22*(1-F8)+F9)*F6)-((INPUTS!$C$6*F7)*F6)*(IF((((INPUTS!$C$6*F7)*F6)*((INPUTS!$C$28/((BOM!$E$22*(1-F8)+F9)*F6))*365/F10))<=0,0.04,IF((((INPUTS!$C$6*F7)*F6)*((INPUTS!$C$28/((BOM!$E$22*(1-F8)+F9)*F6))*365/F10))<=180000,0.04,IF((((INPUTS!$C$6*F7)*F6)*((INPUTS!$C$28/((BOM!$E$22*(1-F8)+F9)*F6))*365/F10))<=360000,((((INPUTS!$C$6*F7)*F6)*((INPUTS!$C$28/((BOM!$E$22*(1-F8)+F9)*F6))*365/F10))*0.073-5940)/(((INPUTS!$C$6*F7)*F6)*((INPUTS!$C$28/((BOM!$E$22*(1-F8)+F9)*F6))*365/F10)),IF((((INPUTS!$C$6*F7)*F6)*((INPUTS!$C$28/((BOM!$E$22*(1-F8)+F9)*F6))*365/F10))<=720000,((((INPUTS!$C$6*F7)*F6)*((INPUTS!$C$28/((BOM!$E$22*(1-F8)+F9)*F6))*365/F10))*0.095-13860)/(((INPUTS!$C$6*F7)*F6)*((INPUTS!$C$28/((BOM!$E$22*(1-F8)+F9)*F6))*365/F10)),IF((((INPUTS!$C$6*F7)*F6)*((INPUTS!$C$28/((BOM!$E$22*(1-F8)+F9)*F6))*365/F10))<=1800000,((((INPUTS!$C$6*F7)*F6)*((INPUTS!$C$28/((BOM!$E$22*(1-F8)+F9)*F6))*365/F10))*0.107-22500)/(((INPUTS!$C$6*F7)*F6)*((INPUTS!$C$28/((BOM!$E$22*(1-F8)+F9)*F6))*365/F10)),IF((((INPUTS!$C$6*F7)*F6)*((INPUTS!$C$28/((BOM!$E$22*(1-F8)+F9)*F6))*365/F10))<=3600000,((((INPUTS!$C$6*F7)*F6)*((INPUTS!$C$28/((BOM!$E$22*(1-F8)+F9)*F6))*365/F10))*0.143-87300)/(((INPUTS!$C$6*F7)*F6)*((INPUTS!$C$28/((BOM!$E$22*(1-F8)+F9)*F6))*365/F10)),((((INPUTS!$C$6*F7)*F6)*((INPUTS!$C$28/((BOM!$E$22*(1-F8)+F9)*F6))*365/F10))*0.19-378000)/(((INPUTS!$C$6*F7)*F6)*((INPUTS!$C$28/((BOM!$E$22*(1-F8)+F9)*F6))*365/F10)))))))))-MIN(((INPUTS!$C$6*F7)*F6)*INPUTS!$C$25,INPUTS!$C$26)) | G19: =(((INPUTS!$C$6*G7)*G6)-((BOM!$E$22*(1-G8)+G9)*G6)-((INPUTS!$C$6*G7)*G6)*(IF((((INPUTS!$C$6*G7)*G6)*((INPUTS!$C$28/((BOM!$E$22*(1-G8)+G9)*G6))*365/G10))<=0,0.04,IF((((INPUTS!$C$6*G7)*G6)*((INPUTS!$C$28/((BOM!$E$22*(1-G8)+G9)*G6))*365/G10))<=180000,0.04,IF((((INPUTS!$C$6*G7)*G6)*((INPUTS!$C$28/((BOM!$E$22*(1-G8)+G9)*G6))*365/G10))<=360000,((((INPUTS!$C$6*G7)*G6)*((INPUTS!$C$28/((BOM!$E$22*(1-G8)+G9)*G6))*365/G10))*0.073-5940)/(((INPUTS!$C$6*G7)*G6)*((INPUTS!$C$28/((BOM!$E$22*(1-G8)+G9)*G6))*365/G10)),IF((((INPUTS!$C$6*G7)*G6)*((INPUTS!$C$28/((BOM!$E$22*(1-G8)+G9)*G6))*365/G10))<=720000,((((INPUTS!$C$6*G7)*G6)*((INPUTS!$C$28/((BOM!$E$22*(1-G8)+G9)*G6))*365/G10))*0.095-13860)/(((INPUTS!$C$6*G7)*G6)*((INPUTS!$C$28/((BOM!$E$22*(1-G8)+G9)*G6))*365/G10)),IF((((INPUTS!$C$6*G7)*G6)*((INPUTS!$C$28/((BOM!$E$22*(1-G8)+G9)*G6))*365/G10))<=1800000,((((INPUTS!$C$6*G7)*G6)*((INPUTS!$C$28/((BOM!$E$22*(1-G8)+G9)*G6))*365/G10))*0.107-22500)/(((INPUTS!$C$6*G7)*G6)*((INPUTS!$C$28/((BOM!$E$22*(1-G8)+G9)*G6))*365/G10)),IF((((INPUTS!$C$6*G7)*G6)*((INPUTS!$C$28/((BOM!$E$22*(1-G8)+G9)*G6))*365/G10))<=3600000,((((INPUTS!$C$6*G7)*G6)*((INPUTS!$C$28/((BOM!$E$22*(1-G8)+G9)*G6))*365/G10))*0.143-87300)/(((INPUTS!$C$6*G7)*G6)*((INPUTS!$C$28/((BOM!$E$22*(1-G8)+G9)*G6))*365/G10)),((((INPUTS!$C$6*G7)*G6)*((INPUTS!$C$28/((BOM!$E$22*(1-G8)+G9)*G6))*365/G10))*0.19-378000)/(((INPUTS!$C$6*G7)*G6)*((INPUTS!$C$28/((BOM!$E$22*(1-G8)+G9)*G6))*365/G10)))))))))-MIN(((INPUTS!$C$6*G7)*G6)*INPUTS!$C$25,INPUTS!$C$26)) | H19: =(((INPUTS!$C$6*H7)*H6)-((BOM!$E$22*(1-H8)+H9)*H6)-((INPUTS!$C$6*H7)*H6)*(IF((((INPUTS!$C$6*H7)*H6)*((INPUTS!$C$28/((BOM!$E$22*(1-H8)+H9)*H6))*365/H10))<=0,0.04,IF((((INPUTS!$C$6*H7)*H6)*((INPUTS!$C$28/((BOM!$E$22*(1-H8)+H9)*H6))*365/H10))<=180000,0.04,IF((((INPUTS!$C$6*H7)*H6)*((INPUTS!$C$28/((BOM!$E$22*(1-H8)+H9)*H6))*365/H10))<=360000,((((INPUTS!$C$6*H7)*H6)*((INPUTS!$C$28/((BOM!$E$22*(1-H8)+H9)*H6))*365/H10))*0.073-5940)/(((INPUTS!$C$6*H7)*H6)*((INPUTS!$C$28/((BOM!$E$22*(1-H8)+H9)*H6))*365/H10)),IF((((INPUTS!$C$6*H7)*H6)*((INPUTS!$C$28/((BOM!$E$22*(1-H8)+H9)*H6))*365/H10))<=720000,((((INPUTS!$C$6*H7)*H6)*((INPUTS!$C$28/((BOM!$E$22*(1-H8)+H9)*H6))*365/H10))*0.095-13860)/(((INPUTS!$C$6*H7)*H6)*((INPUTS!$C$28/((BOM!$E$22*(1-H8)+H9)*H6))*365/H10)),IF((((INPUTS!$C$6*H7)*H6)*((INPUTS!$C$28/((BOM!$E$22*(1-H8)+H9)*H6))*365/H10))<=1800000,((((INPUTS!$C$6*H7)*H6)*((INPUTS!$C$28/((BOM!$E$22*(1-H8)+H9)*H6))*365/H10))*0.107-22500)/(((INPUTS!$C$6*H7)*H6)*((INPUTS!$C$28/((BOM!$E$22*(1-H8)+H9)*H6))*365/H10)),IF((((INPUTS!$C$6*H7)*H6)*((INPUTS!$C$28/((BOM!$E$22*(1-H8)+H9)*H6))*365/H10))<=3600000,((((INPUTS!$C$6*H7)*H6)*((INPUTS!$C$28/((BOM!$E$22*(1-H8)+H9)*H6))*365/H10))*0.143-87300)/(((INPUTS!$C$6*H7)*H6)*((INPUTS!$C$28/((BOM!$E$22*(1-H8)+H9)*H6))*365/H10)),((((INPUTS!$C$6*H7)*H6)*((INPUTS!$C$28/((BOM!$E$22*(1-H8)+H9)*H6))*365/H10))*0.19-378000)/(((INPUTS!$C$6*H7)*H6)*((INPUTS!$C$28/((BOM!$E$22*(1-H8)+H9)*H6))*365/H10)))))))))-MIN(((INPUTS!$C$6*H7)*H6)*INPUTS!$C$25,INPUTS!$C$26))
B21: A YEAR OF LOTS LIKE THIS
B22: Lots the capital can actually carry | C22: =((INPUTS!$C$28/((BOM!$E$22*(1-C8)+C9)*C6))*365/C10) | D22: =((INPUTS!$C$28/((BOM!$E$22*(1-D8)+D9)*D6))*365/D10) | E22: =((INPUTS!$C$28/((BOM!$E$22*(1-E8)+E9)*E6))*365/E10) | F22: =((INPUTS!$C$28/((BOM!$E$22*(1-F8)+F9)*F6))*365/F10) | G22: =((INPUTS!$C$28/((BOM!$E$22*(1-G8)+G9)*G6))*365/G10) | H22: =((INPUTS!$C$28/((BOM!$E$22*(1-H8)+H9)*H6))*365/H10) | I22: Not an assumption: capital ÷ cash per lot × 365 ÷ float days.
B23: Revenue for the year | C23: =(((INPUTS!$C$6*C7)*C6)*((INPUTS!$C$28/((BOM!$E$22*(1-C8)+C9)*C6))*365/C10)) | D23: =(((INPUTS!$C$6*D7)*D6)*((INPUTS!$C$28/((BOM!$E$22*(1-D8)+D9)*D6))*365/D10)) | E23: =(((INPUTS!$C$6*E7)*E6)*((INPUTS!$C$28/((BOM!$E$22*(1-E8)+E9)*E6))*365/E10)) | F23: =(((INPUTS!$C$6*F7)*F6)*((INPUTS!$C$28/((BOM!$E$22*(1-F8)+F9)*F6))*365/F10)) | G23: =(((INPUTS!$C$6*G7)*G6)*((INPUTS!$C$28/((BOM!$E$22*(1-G8)+G9)*G6))*365/G10)) | H23: =(((INPUTS!$C$6*H7)*H6)*((INPUTS!$C$28/((BOM!$E$22*(1-H8)+H9)*H6))*365/H10))
